Workbook

Sheet Rate History
A1: Date | B1: Rate Change | C1: Cumulative Level
A2: 0 | B2: 0 | C2: 1
A3: 43101 | B3: 0.025 | C3: =C2 * (1 + B3) -> 0
A4: 43466 | B4: 0.03 | C4: =C3 * (1 + B4) -> 0
A5: 43831 | B5: -0.015 | C5: =C4 * (1 + B5) -> 0
A6: 44197 | B6: 0.04 | C6: =C5 * (1 + B6) -> 0
A7: 44562 | B7: 0.05 | C7: =C6 * (1 + B7) -> 0
A8: 44927 | B8: 0.035 | C8: =C7 * (1 + B8) -> 0
A9: 45292 | B9: 0.02 | C9: =C8 * (1 + B9) -> 0
A10: 45658 | B10: 0.015 | C10: =C9 * (1 + B10) -> 0
A12: Evaluation Date: | B12: 46022
A13: Current Level: | C13: =VLOOKUP(B12, 'Rate History'!$A$2:$C$10, 3, TRUE) -> 0

Sheet WP Onleveling
A1: Year | B1: Written Premium ($) | C1: Mid-Year Target Date | D1: Historic Auth Level | E1: Factor (Current/Hist) | F1: OnLevel Premium
A2: 2015 | B2: 367378 | C2: =DATE(A2, 7, 1) -> 0 | D2: =VLOOKUP(C2, 'Rate History'!$A$2:$C$10, 3, TRUE) -> 0 | E2: ='Rate History'!$C$13 / D2 -> 0 | F2: =B2 * E2 -> 0
A3: 2016 | B3: 104582 | C3: =DATE(A3, 7, 1) -> 0 | D3: =VLOOKUP(C3, 'Rate History'!$A$2:$C$10, 3, TRUE) -> 0 | E3: ='Rate History'!$C$13 / D3 -> 0 | F3: =B3 * E3 -> 0
A4: 2017 | B4: 497650 | C4: =DATE(A4, 7, 1) -> 0 | D4: =VLOOKUP(C4, 'Rate History'!$A$2:$C$10, 3, TRUE) -> 0 | E4: ='Rate History'!$C$13 / D4 -> 0 | F4: =B4 * E4 -> 0
A5: 2018 | B5: 321482 | C5: =DATE(A5, 7, 1) -> 0 | D5: =VLOOKUP(C5, 'Rate History'!$A$2:$C$10, 3, TRUE) -> 0 | E5: ='Rate History'!$C$13 / D5 -> 0 | F5: =B5 * E5 -> 0
A6: 2019 | B6: 364931 | C6: =DATE(A6, 7, 1) -> 0 | D6: =VLOOKUP(C6, 'Rate History'!$A$2:$C$10, 3, TRUE) -> 0 | E6: ='Rate History'!$C$13 / D6 -> 0 | F6: =B6 * E6 -> 0
A7: 2020 | B7: 314643 | C7: =DATE(A7, 7, 1) -> 0 | D7: =VLOOKUP(C7, 'Rate History'!$A$2:$C$10, 3, TRUE) -> 0 | E7: ='Rate History'!$C$13 / D7 -> 0 | F7: =B7 * E7 -> 0
A8: 2021 | B8: 484462 | C8: =DATE(A8, 7, 1) -> 0 | D8: =VLOOKUP(C8, 'Rate History'!$A$2:$C$10, 3, TRUE) -> 0 | E8: ='Rate History'!$C$13 / D8 -> 0 | F8: =B8 * E8 -> 0
A9: 2022 | B9: 365106 | C9: =DATE(A9, 7, 1) -> 0 | D9: =VLOOKUP(C9, 'Rate History'!$A$2:$C$10, 3, TRUE) -> 0 | E9: ='Rate History'!$C$13 / D9 -> 0 | F9: =B9 * E9 -> 0
A10: 2023 | B10: 208127 | C10: =DATE(A10, 7, 1) -> 0 | D10: =VLOOKUP(C10, 'Rate History'!$A$2:$C$10, 3, TRUE) -> 0 | E10: ='Rate History'!$C$13 / D10 -> 0 | F10: =B10 * E10 -> 0
A11: 2024 | B11: 453117 | C11: =DATE(A11, 7, 1) -> 0 | D11: =VLOOKUP(C11, 'Rate History'!$A$2:$C$10, 3, TRUE) -> 0 | E11: ='Rate History'!$C$13 / D11 -> 0 | F11: =B11 * E11 -> 0

Sheet CY EP Onleveling
A1: Mid-Term Changes: | B1: FALSE | C1: <- Change to TRUE for Vertical Line
A3: Year | B3: Earned Premium ($) | C3: Month 1 Level | D3: Month 2 Level | E3: Month 3 Level | F3: Month 4 Level | G3: Month 5 Level | H3: Month 6 Level | I3: Month 7 Level | J3: Month 8 Level | K3: Month 9 Level | L3: Month 10 Level | M3: Month 11 Level | N3: Month 12 Level | O3: Average CY Level | P3: CY Factor | Q3: CY OnLevel Premium
A4: 2015 | B4: 367378 | C4: =VLOOKUP(IF($B$1, DATE($A4, 1, 15), EDATE(DATE($A4, 1, 15), -6)), 'Rate History'!$A$2:$C$10, 3, TRUE) -> 0 | D4: =VLOOKUP(IF($B$1, DATE($A4, 2, 15), EDATE(DATE($A4, 2, 15), -6)), 'Rate History'!$A$2:$C$10, 3, TRUE) -> 0 | E4: =VLOOKUP(IF($B$1, DATE($A4, 3, 15), EDATE(DATE($A4, 3, 15), -6)), 'Rate History'!$A$2:$C$10, 3, TRUE) -> 0 | F4: =VLOOKUP(IF($B$1, DATE($A4, 4, 15), EDATE(DATE($A4, 4, 15), -6)), 'Rate History'!$A$2:$C$10, 3, TRUE) -> 0 | G4: =VLOOKUP(IF($B$1, DATE($A4, 5, 15), EDATE(DATE($A4, 5, 15), -6)), 'Rate History'!$A$2:$C$10, 3, TRUE) -> 0 | H4: =VLOOKUP(IF($B$1, DATE($A4, 6, 15), EDATE(DATE($A4, 6, 15), -6)), 'Rate History'!$A$2:$C$10, 3, TRUE) -> 0 | I4: =VLOOKUP(IF($B$1, DATE($A4, 7, 15), EDATE(DATE($A4, 7, 15), -6)), 'Rate History'!$A$2:$C$10, 3, TRUE) -> 0 | J4: =VLOOKUP(IF($B$1, DATE($A4, 8, 15), EDATE(DATE($A4, 8, 15), -6)), 'Rate History'!$A$2:$C$10, 3, TRUE) -> 0 | K4: =VLOOKUP(IF($B$1, DATE($A4, 9, 15), EDATE(DATE($A4, 9, 15), -6)), 'Rate History'!$A$2:$C$10, 3, TRUE) -> 0 | L4: =VLOOKUP(IF($B$1, DATE($A4, 10, 15), EDATE(DATE($A4, 10, 15), -6)), 'Rate History'!$A$2:$C$10, 3, TRUE) -> 0 | M4: =VLOOKUP(IF($B$1, DATE($A4, 11, 15), EDATE(DATE($A4, 11, 15), -6)), 'Rate History'!$A$2:$C$10, 3, TRUE) -> 0 | N4: =VLOOKUP(IF($B$1, DATE($A4, 12, 15), EDATE(DATE($A4, 12, 15), -6)), 'Rate History'!$A$2:$C$10, 3, TRUE) -> 0 | O4: =AVERAGE(C4:N4) -> 0 | P4: ='Rate History'!$C$13 / O4 -> 0 | Q4: =$B4 * P4 -> 0
A5: 2016 | B5: 104582 | C5: =VLOOKUP(IF($B$1, DATE($A5, 1, 15), EDATE(DATE($A5, 1, 15), -6)), 'Rate History'!$A$2:$C$10, 3, TRUE) -> 0 | D5: =VLOOKUP(IF($B$1, DATE($A5, 2, 15), EDATE(DATE($A5, 2, 15), -6)), 'Rate History'!$A$2:$C$10, 3, TRUE) -> 0 | E5: =VLOOKUP(IF($B$1, DATE($A5, 3, 15), EDATE(DATE($A5, 3, 15), -6)), 'Rate History'!$A$2:$C$10, 3, TRUE) -> 0 | F5: =VLOOKUP(IF($B$1, DATE($A5, 4, 15), EDATE(DATE($A5, 4, 15), -6)), 'Rate History'!$A$2:$C$10, 3, TRUE) -> 0 | G5: =VLOOKUP(IF($B$1, DATE($A5, 5, 15), EDATE(DATE($A5, 5, 15), -6)), 'Rate History'!$A$2:$C$10, 3, TRUE) -> 0 | H5: =VLOOKUP(IF($B$1, DATE($A5, 6, 15), EDATE(DATE($A5, 6, 15), -6)), 'Rate History'!$A$2:$C$10, 3, TRUE) -> 0 | I5: =VLOOKUP(IF($B$1, DATE($A5, 7, 15), EDATE(DATE($A5, 7, 15), -6)), 'Rate History'!$A$2:$C$10, 3, TRUE) -> 0 | J5: =VLOOKUP(IF($B$1, DATE($A5, 8, 15), EDATE(DATE($A5, 8, 15), -6)), 'Rate History'!$A$2:$C$10, 3, TRUE) -> 0 | K5: =VLOOKUP(IF($B$1, DATE($A5, 9, 15), EDATE(DATE($A5, 9, 15), -6)), 'Rate History'!$A$2:$C$10, 3, TRUE) -> 0 | L5: =VLOOKUP(IF($B$1, DATE($A5, 10, 15), EDATE(DATE($A5, 10, 15), -6)), 'Rate History'!$A$2:$C$10, 3, TRUE) -> 0 | M5: =VLOOKUP(IF($B$1, DATE($A5, 11, 15), EDATE(DATE($A5, 11, 15), -6)), 'Rate History'!$A$2:$C$10, 3, TRUE) -> 0 | N5: =VLOOKUP(IF($B$1, DATE($A5, 12, 15), EDATE(DATE($A5, 12, 15), -6)), 'Rate History'!$A$2:$C$10, 3, TRUE) -> 0 | O5: =AVERAGE(C5:N5) -> 0 | P5: ='Rate History'!$C$13 / O5 -> 0 | Q5: =$B5 * P5 -> 0
A6: 2017 | B6: 497650 | C6: =VLOOKUP(IF($B$1, DATE($A6, 1, 15), EDATE(DATE($A6, 1, 15), -6)), 'Rate History'!$A$2:$C$10, 3, TRUE) -> 0 | D6: =VLOOKUP(IF($B$1, DATE($A6, 2, 15), EDATE(DATE($A6, 2, 15), -6)), 'Rate History'!$A$2:$C$10, 3, TRUE) -> 0 | E6: =VLOOKUP(IF($B$1, DATE($A6, 3, 15), EDATE(DATE($A6, 3, 15), -6)), 'Rate History'!$A$2:$C$10, 3, TRUE) -> 0 | F6: =VLOOKUP(IF($B$1, DATE($A6, 4, 15), EDATE(DATE($A6, 4, 15), -6)), 'Rate History'!$A$2:$C$10, 3, TRUE) -> 0 | G6: =VLOOKUP(IF($B$1, DATE($A6, 5, 15), EDATE(DATE($A6, 5, 15), -6)), 'Rate History'!$A$2:$C$10, 3, TRUE) -> 0 | H6: =VLOOKUP(IF($B$1, DATE($A6, 6, 15), EDATE(DATE($A6, 6, 15), -6)), 'Rate History'!$A$2:$C$10, 3, TRUE) -> 0 | I6: =VLOOKUP(IF($B$1, DATE($A6, 7, 15), EDATE(DATE($A6, 7, 15), -6)), 'Rate History'!$A$2:$C$10, 3, TRUE) -> 0 | J6: =VLOOKUP(IF($B$1, DATE($A6, 8, 15), EDATE(DATE($A6, 8, 15), -6)), 'Rate History'!$A$2:$C$10, 3, TRUE) -> 0 | K6: =VLOOKUP(IF($B$1, DATE($A6, 9, 15), EDATE(DATE($A6, 9, 15), -6)), 'Rate History'!$A$2:$C$10, 3, TRUE) -> 0 | L6: =VLOOKUP(IF($B$1, DATE($A6, 10, 15), EDATE(DATE($A6, 10, 15), -6)), 'Rate History'!$A$2:$C$10, 3, TRUE) -> 0 | M6: =VLOOKUP(IF($B$1, DATE($A6, 11, 15), EDATE(DATE($A6, 11, 15), -6)), 'Rate History'!$A$2:$C$10, 3, TRUE) -> 0 | N6: =VLOOKUP(IF($B$1, DATE($A6, 12, 15), EDATE(DATE($A6, 12, 15), -6)), 'Rate History'!$A$2:$C$10, 3, TRUE) -> 0 | O6: =AVERAGE(C6:N6) -> 0 | P6: ='Rate History'!$C$13 / O6 -> 0 | Q6: =$B6 * P6 -> 0
A7: 2018 | B7: 321482 | C7: =VLOOKUP(IF($B$1, DATE($A7, 1, 15), EDATE(DATE($A7, 1, 15), -6)), 'Rate History'!$A$2:$C$10, 3, TRUE) -> 0 | D7: =VLOOKUP(IF($B$1, DATE($A7, 2, 15), EDATE(DATE($A7, 2, 15), -6)), 'Rate History'!$A$2:$C$10, 3, TRUE) -> 0 | E7: =VLOOKUP(IF($B$1, DATE($A7, 3, 15), EDATE(DATE($A7, 3, 15), -6)), 'Rate History'!$A$2:$C$10, 3, TRUE) -> 0 | F7: =VLOOKUP(IF($B$1, DATE($A7, 4, 15), EDATE(DATE($A7, 4, 15), -6)), 'Rate History'!$A$2:$C$10, 3, TRUE) -> 0 | G7: =VLOOKUP(IF($B$1, DATE($A7, 5, 15), EDATE(DATE($A7, 5, 15), -6)), 'Rate History'!$A$2:$C$10, 3, TRUE) -> 0 | H7: =VLOOKUP(IF($B$1, DATE($A7, 6, 15), EDATE(DATE($A7, 6, 15), -6)), 'Rate History'!$A$2:$C$10, 3, TRUE) -> 0 | I7: =VLOOKUP(IF($B$1, DATE($A7, 7, 15), EDATE(DATE($A7, 7, 15), -6)), 'Rate History'!$A$2:$C$10, 3, TRUE) -> 0 | J7: =VLOOKUP(IF($B$1, DATE($A7, 8, 15), EDATE(DATE($A7, 8, 15), -6)), 'Rate History'!$A$2:$C$10, 3, TRUE) -> 0 | K7: =VLOOKUP(IF($B$1, DATE($A7, 9, 15), EDATE(DATE($A7, 9, 15), -6)), 'Rate History'!$A$2:$C$10, 3, TRUE) -> 0 | L7: =VLOOKUP(IF($B$1, DATE($A7, 10, 15), EDATE(DATE($A7, 10, 15), -6)), 'Rate History'!$A$2:$C$10, 3, TRUE) -> 0 | M7: =VLOOKUP(IF($B$1, DATE($A7, 11, 15), EDATE(DATE($A7, 11, 15), -6)), 'Rate History'!$A$2:$C$10, 3, TRUE) -> 0 | N7: =VLOOKUP(IF($B$1, DATE($A7, 12, 15), EDATE(DATE($A7, 12, 15), -6)), 'Rate History'!$A$2:$C$10, 3, TRUE) -> 0 | O7: =AVERAGE(C7:N7) -> 0 | P7: ='Rate History'!$C$13 / O7 -> 0 | Q7: =$B7 * P7 -> 0
A8: 2019 | B8: 364931 | C8: =VLOOKUP(IF($B$1, DATE($A8, 1, 15), EDATE(DATE($A8, 1, 15), -6)), 'Rate History'!$A$2:$C$10, 3, TRUE) -> 0 | D8: =VLOOKUP(IF($B$1, DATE($A8, 2, 15), EDATE(DATE($A8, 2, 15), -6)), 'Rate History'!$A$2:$C$10, 3, TRUE) -> 0 | E8: =VLOOKUP(IF($B$1, DATE($A8, 3, 15), EDATE(DATE($A8, 3, 15), -6)), 'Rate History'!$A$2:$C$10, 3, TRUE) -> 0 | F8: =VLOOKUP(IF($B$1, DATE($A8, 4, 15), EDATE(DATE($A8, 4, 15), -6)), 'Rate History'!$A$2:$C$10, 3, TRUE) -> 0 | G8: =VLOOKUP(IF($B$1, DATE($A8, 5, 15), EDATE(DATE($A8, 5, 15), -6)), 'Rate History'!$A$2:$C$10, 3, TRUE) -> 0 | H8: =VLOOKUP(IF($B$1, DATE($A8, 6, 15), EDATE(DATE($A8, 6, 15), -6)), 'Rate History'!$A$2:$C$10, 3, TRUE) -> 0 | I8: =VLOOKUP(IF($B$1, DATE($A8, 7, 15), EDATE(DATE($A8, 7, 15), -6)), 'Rate History'!$A$2:$C$10, 3, TRUE) -> 0 | J8: =VLOOKUP(IF($B$1, DATE($A8, 8, 15), EDATE(DATE($A8, 8, 15), -6)), 'Rate History'!$A$2:$C$10, 3, TRUE) -> 0 | K8: =VLOOKUP(IF($B$1, DATE($A8, 9, 15), EDATE(DATE($A8, 9, 15), -6)), 'Rate History'!$A$2:$C$10, 3, TRUE) -> 0 | L8: =VLOOKUP(IF($B$1, DATE($A8, 10, 15), EDATE(DATE($A8, 10, 15), -6)), 'Rate History'!$A$2:$C$10, 3, TRUE) -> 0 | M8: =VLOOKUP(IF($B$1, DATE($A8, 11, 15), EDATE(DATE($A8, 11, 15), -6)), 'Rate History'!$A$2:$C$10, 3, TRUE) -> 0 | N8: =VLOOKUP(IF($B$1, DATE($A8, 12, 15), EDATE(DATE($A8, 12, 15), -6)), 'Rate History'!$A$2:$C$10, 3, TRUE) -> 0 | O8: =AVERAGE(C8:N8) -> 0 | P8: ='Rate History'!$C$13 / O8 -> 0 | Q8: =$B8 * P8 -> 0
A9: 2020 | B9: 314643 | C9: =VLOOKUP(IF($B$1, DATE($A9, 1, 15), EDATE(DATE($A9, 1, 15), -6)), 'Rate History'!$A$2:$C$10, 3, TRUE) -> 0 | D9: =VLOOKUP(IF($B$1, DATE($A9, 2, 15), EDATE(DATE($A9, 2, 15), -6)), 'Rate History'!$A$2:$C$10, 3, TRUE) -> 0 | E9: =VLOOKUP(IF($B$1, DATE($A9, 3, 15), EDATE(DATE($A9, 3, 15), -6)), 'Rate History'!$A$2:$C$10, 3, TRUE) -> 0 | F9: =VLOOKUP(IF($B$1, DATE($A9, 4, 15), EDATE(DATE($A9, 4, 15), -6)), 'Rate History'!$A$2:$C$10, 3, TRUE) -> 0 | G9: =VLOOKUP(IF($B$1, DATE($A9, 5, 15), EDATE(DATE($A9, 5, 15), -6)), 'Rate History'!$A$2:$C$10, 3, TRUE) -> 0 | H9: =VLOOKUP(IF($B$1, DATE($A9, 6, 15), EDATE(DATE($A9, 6, 15), -6)), 'Rate History'!$A$2:$C$10, 3, TRUE) -> 0 | I9: =VLOOKUP(IF($B$1, DATE($A9, 7, 15), EDATE(DATE($A9, 7, 15), -6)), 'Rate History'!$A$2:$C$10, 3, TRUE) -> 0 | J9: =VLOOKUP(IF($B$1, DATE($A9, 8, 15), EDATE(DATE($A9, 8, 15), -6)), 'Rate History'!$A$2:$C$10, 3, TRUE) -> 0 | K9: =VLOOKUP(IF($B$1, DATE($A9, 9, 15), EDATE(DATE($A9, 9, 15), -6)), 'Rate History'!$A$2:$C$10, 3, TRUE) -> 0 | L9: =VLOOKUP(IF($B$1, DATE($A9, 10, 15), EDATE(DATE($A9, 10, 15), -6)), 'Rate History'!$A$2:$C$10, 3, TRUE) -> 0 | M9: =VLOOKUP(IF($B$1, DATE($A9, 11, 15), EDATE(DATE($A9, 11, 15), -6)), 'Rate History'!$A$2:$C$10, 3, TRUE) -> 0 | N9: =VLOOKUP(IF($B$1, DATE($A9, 12, 15), EDATE(DATE($A9, 12, 15), -6)), 'Rate History'!$A$2:$C$10, 3, TRUE) -> 0 | O9: =AVERAGE(C9:N9) -> 0 | P9: ='Rate History'!$C$13 / O9 -> 0 | Q9: =$B9 * P9 -> 0
A10: 2021 | B10: 484462 | C10: =VLOOKUP(IF($B$1, DATE($A10, 1, 15), EDATE(DATE($A10, 1, 15), -6)), 'Rate History'!$A$2:$C$10, 3, TRUE) -> 0 | D10: =VLOOKUP(IF($B$1, DATE($A10, 2, 15), EDATE(DATE($A10, 2, 15), -6)), 'Rate History'!$A$2:$C$10, 3, TRUE) -> 0 | E10: =VLOOKUP(IF($B$1, DATE($A10, 3, 15), EDATE(DATE($A10, 3, 15), -6)), 'Rate History'!$A$2:$C$10, 3, TRUE) -> 0 | F10: =VLOOKUP(IF($B$1, DATE($A10, 4, 15), EDATE(DATE($A10, 4, 15), -6)), 'Rate History'!$A$2:$C$10, 3, TRUE) -> 0 | G10: =VLOOKUP(IF($B$1, DATE($A10, 5, 15), EDATE(DATE($A10, 5, 15), -6)), 'Rate History'!$A$2:$C$10, 3, TRUE) -> 0 | H10: =VLOOKUP(IF($B$1, DATE($A10, 6, 15), EDATE(DATE($A10, 6, 15), -6)), 'Rate History'!$A$2:$C$10, 3, TRUE) -> 0 | I10: =VLOOKUP(IF($B$1, DATE($A10, 7, 15), EDATE(DATE($A10, 7, 15), -6)), 'Rate History'!$A$2:$C$10, 3, TRUE) -> 0 | J10: =VLOOKUP(IF($B$1, DATE($A10, 8, 15), EDATE(DATE($A10, 8, 15), -6)), 'Rate History'!$A$2:$C$10, 3, TRUE) -> 0 | K10: =VLOOKUP(IF($B$1, DATE($A10, 9, 15), EDATE(DATE($A10, 9, 15), -6)), 'Rate History'!$A$2:$C$10, 3, TRUE) -> 0 | L10: =VLOOKUP(IF($B$1, DATE($A10, 10, 15), EDATE(DATE($A10, 10, 15), -6)), 'Rate History'!$A$2:$C$10, 3, TRUE) -> 0 | M10: =VLOOKUP(IF($B$1, DATE($A10, 11, 15), EDATE(DATE($A10, 11, 15), -6)), 'Rate History'!$A$2:$C$10, 3, TRUE) -> 0 | N10: =VLOOKUP(IF($B$1, DATE($A10, 12, 15), EDATE(DATE($A10, 12, 15), -6)), 'Rate History'!$A$2:$C$10, 3, TRUE) -> 0 | O10: =AVERAGE(C10:N10) -> 0 | P10: ='Rate History'!$C$13 / O10 -> 0 | Q10: =$B10 * P10 -> 0
A11: 2022 | B11: 365106 | C11: =VLOOKUP(IF($B$1, DATE($A11, 1, 15), EDATE(DATE($A11, 1, 15), -6)), 'Rate History'!$A$2:$C$10, 3, TRUE) -> 0 | D11: =VLOOKUP(IF($B$1, DATE($A11, 2, 15), EDATE(DATE($A11, 2, 15), -6)), 'Rate History'!$A$2:$C$10, 3, TRUE) -> 0 | E11: =VLOOKUP(IF($B$1, DATE($A11, 3, 15), EDATE(DATE($A11, 3, 15), -6)), 'Rate History'!$A$2:$C$10, 3, TRUE) -> 0 | F11: =VLOOKUP(IF($B$1, DATE($A11, 4, 15), EDATE(DATE($A11, 4, 15), -6)), 'Rate History'!$A$2:$C$10, 3, TRUE) -> 0 | G11: =VLOOKUP(IF($B$1, DATE($A11, 5, 15), EDATE(DATE($A11, 5, 15), -6)), 'Rate History'!$A$2:$C$10, 3, TRUE) -> 0 | H11: =VLOOKUP(IF($B$1, DATE($A11, 6, 15), EDATE(DATE($A11, 6, 15), -6)), 'Rate History'!$A$2:$C$10, 3, TRUE) -> 0 | I11: =VLOOKUP(IF($B$1, DATE($A11, 7, 15), EDATE(DATE($A11, 7, 15), -6)), 'Rate History'!$A$2:$C$10, 3, TRUE) -> 0 | J11: =VLOOKUP(IF($B$1, DATE($A11, 8, 15), EDATE(DATE($A11, 8, 15), -6)), 'Rate History'!$A$2:$C$10, 3, TRUE) -> 0 | K11: =VLOOKUP(IF($B$1, DATE($A11, 9, 15), EDATE(DATE($A11, 9, 15), -6)), 'Rate History'!$A$2:$C$10, 3, TRUE) -> 0 | L11: =VLOOKUP(IF($B$1, DATE($A11, 10, 15), EDATE(DATE($A11, 10, 15), -6)), 'Rate History'!$A$2:$C$10, 3, TRUE) -> 0 | M11: =VLOOKUP(IF($B$1, DATE($A11, 11, 15), EDATE(DATE($A11, 11, 15), -6)), 'Rate History'!$A$2:$C$10, 3, TRUE) -> 0 | N11: =VLOOKUP(IF($B$1, DATE($A11, 12, 15), EDATE(DATE($A11, 12, 15), -6)), 'Rate History'!$A$2:$C$10, 3, TRUE) -> 0 | O11: =AVERAGE(C11:N11) -> 0 | P11: ='Rate History'!$C$13 / O11 -> 0 | Q11: =$B11 * P11 -> 0
A12: 2023 | B12: 208127 | C12: =VLOOKUP(IF($B$1, DATE($A12, 1, 15), EDATE(DATE($A12, 1, 15), -6)), 'Rate History'!$A$2:$C$10, 3, TRUE) -> 0 | D12: =VLOOKUP(IF($B$1, DATE($A12, 2, 15), EDATE(DATE($A12, 2, 15), -6)), 'Rate History'!$A$2:$C$10, 3, TRUE) -> 0 | E12: =VLOOKUP(IF($B$1, DATE($A12, 3, 15), EDATE(DATE($A12, 3, 15), -6)), 'Rate History'!$A$2:$C$10, 3, TRUE) -> 0 | F12: =VLOOKUP(IF($B$1, DATE($A12, 4, 15), EDATE(DATE($A12, 4, 15), -6)), 'Rate History'!$A$2:$C$10, 3, TRUE) -> 0 | G12: =VLOOKUP(IF($B$1, DATE($A12, 5, 15), EDATE(DATE($A12, 5, 15), -6)), 'Rate History'!$A$2:$C$10, 3, TRUE) -> 0 | H12: =VLOOKUP(IF($B$1, DATE($A12, 6, 15), EDATE(DATE($A12, 6, 15), -6)), 'Rate History'!$A$2:$C$10, 3, TRUE) -> 0 | I12: =VLOOKUP(IF($B$1, DATE($A12, 7, 15), EDATE(DATE($A12, 7, 15), -6)), 'Rate History'!$A$2:$C$10, 3, TRUE) -> 0 | J12: =VLOOKUP(IF($B$1, DATE($A12, 8, 15), EDATE(DATE($A12, 8, 15), -6)), 'Rate History'!$A$2:$C$10, 3, TRUE) -> 0 | K12: =VLOOKUP(IF($B$1, DATE($A12, 9, 15), EDATE(DATE($A12, 9, 15), -6)), 'Rate History'!$A$2:$C$10, 3, TRUE) -> 0 | L12: =VLOOKUP(IF($B$1, DATE($A12, 10, 15), EDATE(DATE($A12, 10, 15), -6)), 'Rate History'!$A$2:$C$10, 3, TRUE) -> 0 | M12: =VLOOKUP(IF($B$1, DATE($A12, 11, 15), EDATE(DATE($A12, 11, 15), -6)), 'Rate History'!$A$2:$C$10, 3, TRUE) -> 0 | N12: =VLOOKUP(IF($B$1, DATE($A12, 12, 15), EDATE(DATE($A12, 12, 15), -6)), 'Rate History'!$A$2:$C$10, 3, TRUE) -> 0 | O12: =AVERAGE(C12:N12) -> 0 | P12: ='Rate History'!$C$13 / O12 -> 0 | Q12: =$B12 * P12 -> 0
A13: 2024 | B13: 453117 | C13: =VLOOKUP(IF($B$1, DATE($A13, 1, 15), EDATE(DATE($A13, 1, 15), -6)), 'Rate History'!$A$2:$C$10, 3, TRUE) -> 0 | D13: =VLOOKUP(IF($B$1, DATE($A13, 2, 15), EDATE(DATE($A13, 2, 15), -6)), 'Rate History'!$A$2:$C$10, 3, TRUE) -> 0 | E13: =VLOOKUP(IF($B$1, DATE($A13, 3, 15), EDATE(DATE($A13, 3, 15), -6)), 'Rate History'!$A$2:$C$10, 3, TRUE) -> 0 | F13: =VLOOKUP(IF($B$1, DATE($A13, 4, 15), EDATE(DATE($A13, 4, 15), -6)), 'Rate History'!$A$2:$C$10, 3, TRUE) -> 0 | G13: =VLOOKUP(IF($B$1, DATE($A13, 5, 15), EDATE(DATE($A13, 5, 15), -6)), 'Rate History'!$A$2:$C$10, 3, TRUE) -> 0 | H13: =VLOOKUP(IF($B$1, DATE($A13, 6, 15), EDATE(DATE($A13, 6, 15), -6)), 'Rate History'!$A$2:$C$10, 3, TRUE) -> 0 | I13: =VLOOKUP(IF($B$1, DATE($A13, 7, 15), EDATE(DATE($A13, 7, 15), -6)), 'Rate History'!$A$2:$C$10, 3, TRUE) -> 0 | J13: =VLOOKUP(IF($B$1, DATE($A13, 8, 15), EDATE(DATE($A13, 8, 15), -6)), 'Rate History'!$A$2:$C$10, 3, TRUE) -> 0 | K13: =VLOOKUP(IF($B$1, DATE($A13, 9, 15), EDATE(DATE($A13, 9, 15), -6)), 'Rate History'!$A$2:$C$10, 3, TRUE) -> 0 | L13: =VLOOKUP(IF($B$1, DATE($A13, 10, 15), EDATE(DATE($A13, 10, 15), -6)), 'Rate History'!$A$2:$C$10, 3, TRUE) -> 0 | M13: =VLOOKUP(IF($B$1, DATE($A13, 11, 15), EDATE(DATE($A13, 11, 15), -6)), 'Rate History'!$A$2:$C$10, 3, TRUE) -> 0 | N13: =VLOOKUP(IF($B$1, DATE($A13, 12, 15), EDATE(DATE($A13, 12, 15), -6)), 'Rate History'!$A$2:$C$10, 3, TRUE) -> 0 | O13: =AVERAGE(C13:N13) -> 0 | P13: ='Rate History'!$C$13 / O13 -> 0 | Q13: =$B13 * P13 -> 0

Sheet PY EP Onleveling
A1: Mid-Term Changes: | B1: FALSE | C1: <- Change to TRUE for Vertical Line
A3: Year | B3: Earned Premium ($) | C3: M1 Lvl | D3: M2 Lvl | E3: M3 Lvl | F3: M4 Lvl | G3: M5 Lvl | H3: M6 Lvl | I3: M7 Lvl | J3: M8 Lvl | K3: M9 Lvl | L3: M10 Lvl | M3: M11 Lvl | N3: M12 Lvl | O3: M13 Lvl | P3: M14 Lvl | Q3: M15 Lvl | R3: M16 Lvl | S3: M17 Lvl | T3: M18 Lvl | U3: M19 Lvl | V3: M20 Lvl | W3: M21 Lvl | X3: M22 Lvl | Y3: M23 Lvl | Z3: M24 Lvl | AA3: Wt. Triangle Avg Level | AB3: PY Factor | AC3: PY OnLevel Premium
A4: Triangular Weights -> | C4: 0.0069444444 | D4: 0.013888889 | E4: 0.020833333 | F4: 0.027777778 | G4: 0.034722222 | H4: 0.041666667 | I4: 0.048611111 | J4: 0.055555556 | K4: 0.0625 | L4: 0.069444444 | M4: 0.076388889 | N4: 0.083333333 | O4: 0.083333333 | P4: 0.076388889 | Q4: 0.069444444 | R4: 0.0625 | S4: 0.055555556 | T4: 0.048611111 | U4: 0.041666667 | V4: 0.034722222 | W4: 0.027777778 | X4: 0.020833333 | Y4: 0.013888889 | Z4: 0.0069444444
A5: 2015 | B5: 367378 | C5: =VLOOKUP(IF($B$1, DATE($A5 + INT((1-1)/12), MOD(1-1,12)+1, 15), EDATE(DATE($A5 + INT((1-1)/12), MOD(1-1,12)+1, 15), -6)), 'Rate History'!$A$2:$C$10, 3, TRUE) -> 0 | D5: =VLOOKUP(IF($B$1, DATE($A5 + INT((2-1)/12), MOD(2-1,12)+1, 15), EDATE(DATE($A5 + INT((2-1)/12), MOD(2-1,12)+1, 15), -6)), 'Rate History'!$A$2:$C$10, 3, TRUE) -> 0 | E5: =VLOOKUP(IF($B$1, DATE($A5 + INT((3-1)/12), MOD(3-1,12)+1, 15), EDATE(DATE($A5 + INT((3-1)/12), MOD(3-1,12)+1, 15), -6)), 'Rate History'!$A$2:$C$10, 3, TRUE) -> 0 | F5: =VLOOKUP(IF($B$1, DATE($A5 + INT((4-1)/12), MOD(4-1,12)+1, 15), EDATE(DATE($A5 + INT((4-1)/12), MOD(4-1,12)+1, 15), -6)), 'Rate History'!$A$2:$C$10, 3, TRUE) -> 0 | G5: =VLOOKUP(IF($B$1, DATE($A5 + INT((5-1)/12), MOD(5-1,12)+1, 15), EDATE(DATE($A5 + INT((5-1)/12), MOD(5-1,12)+1, 15), -6)), 'Rate History'!$A$2:$C$10, 3, TRUE) -> 0 | H5: =VLOOKUP(IF($B$1, DATE($A5 + INT((6-1)/12), MOD(6-1,12)+1, 15), EDATE(DATE($A5 + INT((6-1)/12), MOD(6-1,12)+1, 15), -6)), 'Rate History'!$A$2:$C$10, 3, TRUE) -> 0 | I5: =VLOOKUP(IF($B$1, DATE($A5 + INT((7-1)/12), MOD(7-1,12)+1, 15), EDATE(DATE($A5 + INT((7-1)/12), MOD(7-1,12)+1, 15), -6)), 'Rate History'!$A$2:$C$10, 3, TRUE) -> 0 | J5: =VLOOKUP(IF($B$1, DATE($A5 + INT((8-1)/12), MOD(8-1,12)+1, 15), EDATE(DATE($A5 + INT((8-1)/12), MOD(8-1,12)+1, 15), -6)), 'Rate History'!$A$2:$C$10, 3, TRUE) -> 0 | K5: =VLOOKUP(IF($B$1, DATE($A5 + INT((9-1)/12), MOD(9-1,12)+1, 15), EDATE(DATE($A5 + INT((9-1)/12), MOD(9-1,12)+1, 15), -6)), 'Rate History'!$A$2:$C$10, 3, TRUE) -> 0 | L5: =VLOOKUP(IF($B$1, DATE($A5 + INT((10-1)/12), MOD(10-1,12)+1, 15), EDATE(DATE($A5 + INT((10-1)/12), MOD(10-1,12)+1, 15), -6)), 'Rate History'!$A$2:$C$10, 3, TRUE) -> 0 | M5: =VLOOKUP(IF($B$1, DATE($A5 + INT((11-1)/12), MOD(11-1,12)+1, 15), EDATE(DATE($A5 + INT((11-1)/12), MOD(11-1,12)+1, 15), -6)), 'Rate History'!$A$2:$C$10, 3, TRUE) -> 0 | N5: =VLOOKUP(IF($B$1, DATE($A5 + INT((12-1)/12), MOD(12-1,12)+1, 15), EDATE(DATE($A5 + INT((12-1)/12), MOD(12-1,12)+1, 15), -6)), 'Rate History'!$A$2:$C$10, 3, TRUE) -> 0 | O5: =VLOOKUP(IF($B$1, DATE($A5 + INT((13-1)/12), MOD(13-1,12)+1, 15), EDATE(DATE($A5 + INT((13-1)/12), MOD(13-1,12)+1, 15), -6)), 'Rate History'!$A$2:$C$10, 3, TRUE) -> 0 | P5: =VLOOKUP(IF($B$1, DATE($A5 + INT((14-1)/12), MOD(14-1,12)+1, 15), EDATE(DATE($A5 + INT((14-1)/12), MOD(14-1,12)+1, 15), -6)), 'Rate History'!$A$2:$C$10, 3, TRUE) -> 0 | Q5: =VLOOKUP(IF($B$1, DATE($A5 + INT((15-1)/12), MOD(15-1,12)+1, 15), EDATE(DATE($A5 + INT((15-1)/12), MOD(15-1,12)+1, 15), -6)), 'Rate History'!$A$2:$C$10, 3, TRUE) -> 0 | R5: =VLOOKUP(IF($B$1, DATE($A5 + INT((16-1)/12), MOD(16-1,12)+1, 15), EDATE(DATE($A5 + INT((16-1)/12), MOD(16-1,12)+1, 15), -6)), 'Rate History'!$A$2:$C$10, 3, TRUE) -> 0 | S5: =VLOOKUP(IF($B$1, DATE($A5 + INT((17-1)/12), MOD(17-1,12)+1, 15), EDATE(DATE($A5 + INT((17-1)/12), MOD(17-1,12)+1, 15), -6)), 'Rate History'!$A$2:$C$10, 3, TRUE) -> 0 | T5: =VLOOKUP(IF($B$1, DATE($A5 + INT((18-1)/12), MOD(18-1,12)+1, 15), EDATE(DATE($A5 + INT((18-1)/12), MOD(18-1,12)+1, 15), -6)), 'Rate History'!$A$2:$C$10, 3, TRUE) -> 0 | U5: =VLOOKUP(IF($B$1, DATE($A5 + INT((19-1)/12), MOD(19-1,12)+1, 15), EDATE(DATE($A5 + INT((19-1)/12), MOD(19-1,12)+1, 15), -6)), 'Rate History'!$A$2:$C$10, 3, TRUE) -> 0 | V5: =VLOOKUP(IF($B$1, DATE($A5 + INT((20-1)/12), MOD(20-1,12)+1, 15), EDATE(DATE($A5 + INT((20-1)/12), MOD(20-1,12)+1, 15), -6)), 'Rate History'!$A$2:$C$10, 3, TRUE) -> 0 | W5: =VLOOKUP(IF($B$1, DATE($A5 + INT((21-1)/12), MOD(21-1,12)+1, 15), EDATE(DATE($A5 + INT((21-1)/12), MOD(21-1,12)+1, 15), -6)), 'Rate History'!$A$2:$C$10, 3, TRUE) -> 0 | X5: =VLOOKUP(IF($B$1, DATE($A5 + INT((22-1)/12), MOD(22-1,12)+1, 15), EDATE(DATE($A5 + INT((22-1)/12), MOD(22-1,12)+1, 15), -6)), 'Rate History'!$A$2:$C$10, 3, TRUE) -> 0 | Y5: =VLOOKUP(IF($B$1, DATE($A5 + INT((23-1)/12), MOD(23-1,12)+1, 15), EDATE(DATE($A5 + INT((23-1)/12), MOD(23-1,12)+1, 15), -6)), 'Rate History'!$A$2:$C$10, 3, TRUE) -> 0 | Z5: =VLOOKUP(IF($B$1, DATE($A5 + INT((24-1)/12), MOD(24-1,12)+1, 15), EDATE(DATE($A5 + INT((24-1)/12), MOD(24-1,12)+1, 15), -6)), 'Rate History'!$A$2:$C$10, 3, TRUE) -> 0 | AA5: =SUMPRODUCT(C$4:Z$4, C5:Z5) -> 0 | AB5: ='Rate History'!$C$13 / AA5 -> 0 | AC5: =$B5 * AB5 -> 0
A6: 2016 | B6: 104582 | C6: =VLOOKUP(IF($B$1, DATE($A6 + INT((1-1)/12), MOD(1-1,12)+1, 15), EDATE(DATE($A6 + INT((1-1)/12), MOD(1-1,12)+1, 15), -6)), 'Rate History'!$A$2:$C$10, 3, TRUE) -> 0 | D6: =VLOOKUP(IF($B$1, DATE($A6 + INT((2-1)/12), MOD(2-1,12)+1, 15), EDATE(DATE($A6 + INT((2-1)/12), MOD(2-1,12)+1, 15), -6)), 'Rate History'!$A$2:$C$10, 3, TRUE) -> 0 | E6: =VLOOKUP(IF($B$1, DATE($A6 + INT((3-1)/12), MOD(3-1,12)+1, 15), EDATE(DATE($A6 + INT((3-1)/12), MOD(3-1,12)+1, 15), -6)), 'Rate History'!$A$2:$C$10, 3, TRUE) -> 0 | F6: =VLOOKUP(IF($B$1, DATE($A6 + INT((4-1)/12), MOD(4-1,12)+1, 15), EDATE(DATE($A6 + INT((4-1)/12), MOD(4-1,12)+1, 15), -6)), 'Rate History'!$A$2:$C$10, 3, TRUE) -> 0 | G6: =VLOOKUP(IF($B$1, DATE($A6 + INT((5-1)/12), MOD(5-1,12)+1, 15), EDATE(DATE($A6 + INT((5-1)/12), MOD(5-1,12)+1, 15), -6)), 'Rate History'!$A$2:$C$10, 3, TRUE) -> 0 | H6: =VLOOKUP(IF($B$1, DATE($A6 + INT((6-1)/12), MOD(6-1,12)+1, 15), EDATE(DATE($A6 + INT((6-1)/12), MOD(6-1,12)+1, 15), -6)), 'Rate History'!$A$2:$C$10, 3, TRUE) -> 0 | I6: =VLOOKUP(IF($B$1, DATE($A6 + INT((7-1)/12), MOD(7-1,12)+1, 15), EDATE(DATE($A6 + INT((7-1)/12), MOD(7-1,12)+1, 15), -6)), 'Rate History'!$A$2:$C$10, 3, TRUE) -> 0 | J6: =VLOOKUP(IF($B$1, DATE($A6 + INT((8-1)/12), MOD(8-1,12)+1, 15), EDATE(DATE($A6 + INT((8-1)/12), MOD(8-1,12)+1, 15), -6)), 'Rate History'!$A$2:$C$10, 3, TRUE) -> 0 | K6: =VLOOKUP(IF($B$1, DATE($A6 + INT((9-1)/12), MOD(9-1,12)+1, 15), EDATE(DATE($A6 + INT((9-1)/12), MOD(9-1,12)+1, 15), -6)), 'Rate History'!$A$2:$C$10, 3, TRUE) -> 0 | L6: =VLOOKUP(IF($B$1, DATE($A6 + INT((10-1)/12), MOD(10-1,12)+1, 15), EDATE(DATE($A6 + INT((10-1)/12), MOD(10-1,12)+1, 15), -6)), 'Rate History'!$A$2:$C$10, 3, TRUE) -> 0 | M6: =VLOOKUP(IF($B$1, DATE($A6 + INT((11-1)/12), MOD(11-1,12)+1, 15), EDATE(DATE($A6 + INT((11-1)/12), MOD(11-1,12)+1, 15), -6)), 'Rate History'!$A$2:$C$10, 3, TRUE) -> 0 | N6: =VLOOKUP(IF($B$1, DATE($A6 + INT((12-1)/12), MOD(12-1,12)+1, 15), EDATE(DATE($A6 + INT((12-1)/12), MOD(12-1,12)+1, 15), -6)), 'Rate History'!$A$2:$C$10, 3, TRUE) -> 0 | O6: =VLOOKUP(IF($B$1, DATE($A6 + INT((13-1)/12), MOD(13-1,12)+1, 15), EDATE(DATE($A6 + INT((13-1)/12), MOD(13-1,12)+1, 15), -6)), 'Rate History'!$A$2:$C$10, 3, TRUE) -> 0 | P6: =VLOOKUP(IF($B$1, DATE($A6 + INT((14-1)/12), MOD(14-1,12)+1, 15), EDATE(DATE($A6 + INT((14-1)/12), MOD(14-1,12)+1, 15), -6)), 'Rate History'!$A$2:$C$10, 3, TRUE) -> 0 | Q6: =VLOOKUP(IF($B$1, DATE($A6 + INT((15-1)/12), MOD(15-1,12)+1, 15), EDATE(DATE($A6 + INT((15-1)/12), MOD(15-1,12)+1, 15), -6)), 'Rate History'!$A$2:$C$10, 3, TRUE) -> 0 | R6: =VLOOKUP(IF($B$1, DATE($A6 + INT((16-1)/12), MOD(16-1,12)+1, 15), EDATE(DATE($A6 + INT((16-1)/12), MOD(16-1,12)+1, 15), -6)), 'Rate History'!$A$2:$C$10, 3, TRUE) -> 0 | S6: =VLOOKUP(IF($B$1, DATE($A6 + INT((17-1)/12), MOD(17-1,12)+1, 15), EDATE(DATE($A6 + INT((17-1)/12), MOD(17-1,12)+1, 15), -6)), 'Rate History'!$A$2:$C$10, 3, TRUE) -> 0 | T6: =VLOOKUP(IF($B$1, DATE($A6 + INT((18-1)/12), MOD(18-1,12)+1, 15), EDATE(DATE($A6 + INT((18-1)/12), MOD(18-1,12)+1, 15), -6)), 'Rate History'!$A$2:$C$10, 3, TRUE) -> 0 | U6: =VLOOKUP(IF($B$1, DATE($A6 + INT((19-1)/12), MOD(19-1,12)+1, 15), EDATE(DATE($A6 + INT((19-1)/12), MOD(19-1,12)+1, 15), -6)), 'Rate History'!$A$2:$C$10, 3, TRUE) -> 0 | V6: =VLOOKUP(IF($B$1, DATE($A6 + INT((20-1)/12), MOD(20-1,12)+1, 15), EDATE(DATE($A6 + INT((20-1)/12), MOD(20-1,12)+1, 15), -6)), 'Rate History'!$A$2:$C$10, 3, TRUE) -> 0 | W6: =VLOOKUP(IF($B$1, DATE($A6 + INT((21-1)/12), MOD(21-1,12)+1, 15), EDATE(DATE($A6 + INT((21-1)/12), MOD(21-1,12)+1, 15), -6)), 'Rate History'!$A$2:$C$10, 3, TRUE) -> 0 | X6: =VLOOKUP(IF($B$1, DATE($A6 + INT((22-1)/12), MOD(22-1,12)+1, 15), EDATE(DATE($A6 + INT((22-1)/12), MOD(22-1,12)+1, 15), -6)), 'Rate History'!$A$2:$C$10, 3, TRUE) -> 0 | Y6: =VLOOKUP(IF($B$1, DATE($A6 + INT((23-1)/12), MOD(23-1,12)+1, 15), EDATE(DATE($A6 + INT((23-1)/12), MOD(23-1,12)+1, 15), -6)), 'Rate History'!$A$2:$C$10, 3, TRUE) -> 0 | Z6: =VLOOKUP(IF($B$1, DATE($A6 + INT((24-1)/12), MOD(24-1,12)+1, 15), EDATE(DATE($A6 + INT((24-1)/12), MOD(24-1,12)+1, 15), -6)), 'Rate History'!$A$2:$C$10, 3, TRUE) -> 0 | AA6: =SUMPRODUCT(C$4:Z$4, C6:Z6) -> 0 | AB6: ='Rate History'!$C$13 / AA6 -> 0 | AC6: =$B6 * AB6 -> 0
A7: 2017 | B7: 497650 | C7: =VLOOKUP(IF($B$1, DATE($A7 + INT((1-1)/12), MOD(1-1,12)+1, 15), EDATE(DATE($A7 + INT((1-1)/12), MOD(1-1,12)+1, 15), -6)), 'Rate History'!$A$2:$C$10, 3, TRUE) -> 0 | D7: =VLOOKUP(IF($B$1, DATE($A7 + INT((2-1)/12), MOD(2-1,12)+1, 15), EDATE(DATE($A7 + INT((2-1)/12), MOD(2-1,12)+1, 15), -6)), 'Rate History'!$A$2:$C$10, 3, TRUE) -> 0 | E7: =VLOOKUP(IF($B$1, DATE($A7 + INT((3-1)/12), MOD(3-1,12)+1, 15), EDATE(DATE($A7 + INT((3-1)/12), MOD(3-1,12)+1, 15), -6)), 'Rate History'!$A$2:$C$10, 3, TRUE) -> 0 | F7: =VLOOKUP(IF($B$1, DATE($A7 + INT((4-1)/12), MOD(4-1,12)+1, 15), EDATE(DATE($A7 + INT((4-1)/12), MOD(4-1,12)+1, 15), -6)), 'Rate History'!$A$2:$C$10, 3, TRUE) -> 0 | G7: =VLOOKUP(IF($B$1, DATE($A7 + INT((5-1)/12), MOD(5-1,12)+1, 15), EDATE(DATE($A7 + INT((5-1)/12), MOD(5-1,12)+1, 15), -6)), 'Rate History'!$A$2:$C$10, 3, TRUE) -> 0 | H7: =VLOOKUP(IF($B$1, DATE($A7 + INT((6-1)/12), MOD(6-1,12)+1, 15), EDATE(DATE($A7 + INT((6-1)/12), MOD(6-1,12)+1, 15), -6)), 'Rate History'!$A$2:$C$10, 3, TRUE) -> 0 | I7: =VLOOKUP(IF($B$1, DATE($A7 + INT((7-1)/12), MOD(7-1,12)+1, 15), EDATE(DATE($A7 + INT((7-1)/12), MOD(7-1,12)+1, 15), -6)), 'Rate History'!$A$2:$C$10, 3, TRUE) -> 0 | J7: =VLOOKUP(IF($B$1, DATE($A7 + INT((8-1)/12), MOD(8-1,12)+1, 15), EDATE(DATE($A7 + INT((8-1)/12), MOD(8-1,12)+1, 15), -6)), 'Rate History'!$A$2:$C$10, 3, TRUE) -> 0 | K7: =VLOOKUP(IF($B$1, DATE($A7 + INT((9-1)/12), MOD(9-1,12)+1, 15), EDATE(DATE($A7 + INT((9-1)/12), MOD(9-1,12)+1, 15), -6)), 'Rate History'!$A$2:$C$10, 3, TRUE) -> 0 | L7: =VLOOKUP(IF($B$1, DATE($A7 + INT((10-1)/12), MOD(10-1,12)+1, 15), EDATE(DATE($A7 + INT((10-1)/12), MOD(10-1,12)+1, 15), -6)), 'Rate History'!$A$2:$C$10, 3, TRUE) -> 0 | M7: =VLOOKUP(IF($B$1, DATE($A7 + INT((11-1)/12), MOD(11-1,12)+1, 15), EDATE(DATE($A7 + INT((11-1)/12), MOD(11-1,12)+1, 15), -6)), 'Rate History'!$A$2:$C$10, 3, TRUE) -> 0 | N7: =VLOOKUP(IF($B$1, DATE($A7 + INT((12-1)/12), MOD(12-1,12)+1, 15), EDATE(DATE($A7 + INT((12-1)/12), MOD(12-1,12)+1, 15), -6)), 'Rate History'!$A$2:$C$10, 3, TRUE) -> 0 | O7: =VLOOKUP(IF($B$1, DATE($A7 + INT((13-1)/12), MOD(13-1,12)+1, 15), EDATE(DATE($A7 + INT((13-1)/12), MOD(13-1,12)+1, 15), -6)), 'Rate History'!$A$2:$C$10, 3, TRUE) -> 0 | P7: =VLOOKUP(IF($B$1, DATE($A7 + INT((14-1)/12), MOD(14-1,12)+1, 15), EDATE(DATE($A7 + INT((14-1)/12), MOD(14-1,12)+1, 15), -6)), 'Rate History'!$A$2:$C$10, 3, TRUE) -> 0 | Q7: =VLOOKUP(IF($B$1, DATE($A7 + INT((15-1)/12), MOD(15-1,12)+1, 15), EDATE(DATE($A7 + INT((15-1)/12), MOD(15-1,12)+1, 15), -6)), 'Rate History'!$A$2:$C$10, 3, TRUE) -> 0 | R7: =VLOOKUP(IF($B$1, DATE($A7 + INT((16-1)/12), MOD(16-1,12)+1, 15), EDATE(DATE($A7 + INT((16-1)/12), MOD(16-1,12)+1, 15), -6)), 'Rate History'!$A$2:$C$10, 3, TRUE) -> 0 | S7: =VLOOKUP(IF($B$1, DATE($A7 + INT((17-1)/12), MOD(17-1,12)+1, 15), EDATE(DATE($A7 + INT((17-1)/12), MOD(17-1,12)+1, 15), -6)), 'Rate History'!$A$2:$C$10, 3, TRUE) -> 0 | T7: =VLOOKUP(IF($B$1, DATE($A7 + INT((18-1)/12), MOD(18-1,12)+1, 15), EDATE(DATE($A7 + INT((18-1)/12), MOD(18-1,12)+1, 15), -6)), 'Rate History'!$A$2:$C$10, 3, TRUE) -> 0 | U7: =VLOOKUP(IF($B$1, DATE($A7 + INT((19-1)/12), MOD(19-1,12)+1, 15), EDATE(DATE($A7 + INT((19-1)/12), MOD(19-1,12)+1, 15), -6)), 'Rate History'!$A$2:$C$10, 3, TRUE) -> 0 | V7: =VLOOKUP(IF($B$1, DATE($A7 + INT((20-1)/12), MOD(20-1,12)+1, 15), EDATE(DATE($A7 + INT((20-1)/12), MOD(20-1,12)+1, 15), -6)), 'Rate History'!$A$2:$C$10, 3, TRUE) -> 0 | W7: =VLOOKUP(IF($B$1, DATE($A7 + INT((21-1)/12), MOD(21-1,12)+1, 15), EDATE(DATE($A7 + INT((21-1)/12), MOD(21-1,12)+1, 15), -6)), 'Rate History'!$A$2:$C$10, 3, TRUE) -> 0 | X7: =VLOOKUP(IF($B$1, DATE($A7 + INT((22-1)/12), MOD(22-1,12)+1, 15), EDATE(DATE($A7 + INT((22-1)/12), MOD(22-1,12)+1, 15), -6)), 'Rate History'!$A$2:$C$10, 3, TRUE) -> 0 | Y7: =VLOOKUP(IF($B$1, DATE($A7 + INT((23-1)/12), MOD(23-1,12)+1, 15), EDATE(DATE($A7 + INT((23-1)/12), MOD(23-1,12)+1, 15), -6)), 'Rate History'!$A$2:$C$10, 3, TRUE) -> 0 | Z7: =VLOOKUP(IF($B$1, DATE($A7 + INT((24-1)/12), MOD(24-1,12)+1, 15), EDATE(DATE($A7 + INT((24-1)/12), MOD(24-1,12)+1, 15), -6)), 'Rate History'!$A$2:$C$10, 3, TRUE) -> 0 | AA7: =SUMPRODUCT(C$4:Z$4, C7:Z7) -> 0 | AB7: ='Rate History'!$C$13 / AA7 -> 0 | AC7: =$B7 * AB7 -> 0
A8: 2018 | B8: 321482 | C8: =VLOOKUP(IF($B$1, DATE($A8 + INT((1-1)/12), MOD(1-1,12)+1, 15), EDATE(DATE($A8 + INT((1-1)/12), MOD(1-1,12)+1, 15), -6)), 'Rate History'!$A$2:$C$10, 3, TRUE) -> 0 | D8: =VLOOKUP(IF($B$1, DATE($A8 + INT((2-1)/12), MOD(2-1,12)+1, 15), EDATE(DATE($A8 + INT((2-1)/12), MOD(2-1,12)+1, 15), -6)), 'Rate History'!$A$2:$C$10, 3, TRUE) -> 0 | E8: =VLOOKUP(IF($B$1, DATE($A8 + INT((3-1)/12), MOD(3-1,12)+1, 15), EDATE(DATE($A8 + INT((3-1)/12), MOD(3-1,12)+1, 15), -6)), 'Rate History'!$A$2:$C$10, 3, TRUE) -> 0 | F8: =VLOOKUP(IF($B$1, DATE($A8 + INT((4-1)/12), MOD(4-1,12)+1, 15), EDATE(DATE($A8 + INT((4-1)/12), MOD(4-1,12)+1, 15), -6)), 'Rate History'!$A$2:$C$10, 3, TRUE) -> 0 | G8: =VLOOKUP(IF($B$1, DATE($A8 + INT((5-1)/12), MOD(5-1,12)+1, 15), EDATE(DATE($A8 + INT((5-1)/12), MOD(5-1,12)+1, 15), -6)), 'Rate History'!$A$2:$C$10, 3, TRUE) -> 0 | H8: =VLOOKUP(IF($B$1, DATE($A8 + INT((6-1)/12), MOD(6-1,12)+1, 15), EDATE(DATE($A8 + INT((6-1)/12), MOD(6-1,12)+1, 15), -6)), 'Rate History'!$A$2:$C$10, 3, TRUE) -> 0 | I8: =VLOOKUP(IF($B$1, DATE($A8 + INT((7-1)/12), MOD(7-1,12)+1, 15), EDATE(DATE($A8 + INT((7-1)/12), MOD(7-1,12)+1, 15), -6)), 'Rate History'!$A$2:$C$10, 3, TRUE) -> 0 | J8: =VLOOKUP(IF($B$1, DATE($A8 + INT((8-1)/12), MOD(8-1,12)+1, 15), EDATE(DATE($A8 + INT((8-1)/12), MOD(8-1,12)+1, 15), -6)), 'Rate History'!$A$2:$C$10, 3, TRUE) -> 0 | K8: =VLOOKUP(IF($B$1, DATE($A8 + INT((9-1)/12), MOD(9-1,12)+1, 15), EDATE(DATE($A8 + INT((9-1)/12), MOD(9-1,12)+1, 15), -6)), 'Rate History'!$A$2:$C$10, 3, TRUE) -> 0 | L8: =VLOOKUP(IF($B$1, DATE($A8 + INT((10-1)/12), MOD(10-1,12)+1, 15), EDATE(DATE($A8 + INT((10-1)/12), MOD(10-1,12)+1, 15), -6)), 'Rate History'!$A$2:$C$10, 3, TRUE) -> 0 | M8: =VLOOKUP(IF($B$1, DATE($A8 + INT((11-1)/12), MOD(11-1,12)+1, 15), EDATE(DATE($A8 + INT((11-1)/12), MOD(11-1,12)+1, 15), -6)), 'Rate History'!$A$2:$C$10, 3, TRUE) -> 0 | N8: =VLOOKUP(IF($B$1, DATE($A8 + INT((12-1)/12), MOD(12-1,12)+1, 15), EDATE(DATE($A8 + INT((12-1)/12), MOD(12-1,12)+1, 15), -6)), 'Rate History'!$A$2:$C$10, 3, TRUE) -> 0 | O8: =VLOOKUP(IF($B$1, DATE($A8 + INT((13-1)/12), MOD(13-1,12)+1, 15), EDATE(DATE($A8 + INT((13-1)/12), MOD(13-1,12)+1, 15), -6)), 'Rate History'!$A$2:$C$10, 3, TRUE) -> 0 | P8: =VLOOKUP(IF($B$1, DATE($A8 + INT((14-1)/12), MOD(14-1,12)+1, 15), EDATE(DATE($A8 + INT((14-1)/12), MOD(14-1,12)+1, 15), -6)), 'Rate History'!$A$2:$C$10, 3, TRUE) -> 0 | Q8: =VLOOKUP(IF($B$1, DATE($A8 + INT((15-1)/12), MOD(15-1,12)+1, 15), EDATE(DATE($A8 + INT((15-1)/12), MOD(15-1,12)+1, 15), -6)), 'Rate History'!$A$2:$C$10, 3, TRUE) -> 0 | R8: =VLOOKUP(IF($B$1, DATE($A8 + INT((16-1)/12), MOD(16-1,12)+1, 15), EDATE(DATE($A8 + INT((16-1)/12), MOD(16-1,12)+1, 15), -6)), 'Rate History'!$A$2:$C$10, 3, TRUE) -> 0 | S8: =VLOOKUP(IF($B$1, DATE($A8 + INT((17-1)/12), MOD(17-1,12)+1, 15), EDATE(DATE($A8 + INT((17-1)/12), MOD(17-1,12)+1, 15), -6)), 'Rate History'!$A$2:$C$10, 3, TRUE) -> 0 | T8: =VLOOKUP(IF($B$1, DATE($A8 + INT((18-1)/12), MOD(18-1,12)+1, 15), EDATE(DATE($A8 + INT((18-1)/12), MOD(18-1,12)+1, 15), -6)), 'Rate History'!$A$2:$C$10, 3, TRUE) -> 0 | U8: =VLOOKUP(IF($B$1, DATE($A8 + INT((19-1)/12), MOD(19-1,12)+1, 15), EDATE(DATE($A8 + INT((19-1)/12), MOD(19-1,12)+1, 15), -6)), 'Rate History'!$A$2:$C$10, 3, TRUE) -> 0 | V8: =VLOOKUP(IF($B$1, DATE($A8 + INT((20-1)/12), MOD(20-1,12)+1, 15), EDATE(DATE($A8 + INT((20-1)/12), MOD(20-1,12)+1, 15), -6)), 'Rate History'!$A$2:$C$10, 3, TRUE) -> 0 | W8: =VLOOKUP(IF($B$1, DATE($A8 + INT((21-1)/12), MOD(21-1,12)+1, 15), EDATE(DATE($A8 + INT((21-1)/12), MOD(21-1,12)+1, 15), -6)), 'Rate History'!$A$2:$C$10, 3, TRUE) -> 0 | X8: =VLOOKUP(IF($B$1, DATE($A8 + INT((22-1)/12), MOD(22-1,12)+1, 15), EDATE(DATE($A8 + INT((22-1)/12), MOD(22-1,12)+1, 15), -6)), 'Rate History'!$A$2:$C$10, 3, TRUE) -> 0 | Y8: =VLOOKUP(IF($B$1, DATE($A8 + INT((23-1)/12), MOD(23-1,12)+1, 15), EDATE(DATE($A8 + INT((23-1)/12), MOD(23-1,12)+1, 15), -6)), 'Rate History'!$A$2:$C$10, 3, TRUE) -> 0 | Z8: =VLOOKUP(IF($B$1, DATE($A8 + INT((24-1)/12), MOD(24-1,12)+1, 15), EDATE(DATE($A8 + INT((24-1)/12), MOD(24-1,12)+1, 15), -6)), 'Rate History'!$A$2:$C$10, 3, TRUE) -> 0 | AA8: =SUMPRODUCT(C$4:Z$4, C8:Z8) -> 0 | AB8: ='Rate History'!$C$13 / AA8 -> 0 | AC8: =$B8 * AB8 -> 0
A9: 2019 | B9: 364931 | C9: =VLOOKUP(IF($B$1, DATE($A9 + INT((1-1)/12), MOD(1-1,12)+1, 15), EDATE(DATE($A9 + INT((1-1)/12), MOD(1-1,12)+1, 15), -6)), 'Rate History'!$A$2:$C$10, 3, TRUE) -> 0 | D9: =VLOOKUP(IF($B$1, DATE($A9 + INT((2-1)/12), MOD(2-1,12)+1, 15), EDATE(DATE($A9 + INT((2-1)/12), MOD(2-1,12)+1, 15), -6)), 'Rate History'!$A$2:$C$10, 3, TRUE) -> 0 | E9: =VLOOKUP(IF($B$1, DATE($A9 + INT((3-1)/12), MOD(3-1,12)+1, 15), EDATE(DATE($A9 + INT((3-1)/12), MOD(3-1,12)+1, 15), -6)), 'Rate History'!$A$2:$C$10, 3, TRUE) -> 0 | F9: =VLOOKUP(IF($B$1, DATE($A9 + INT((4-1)/12), MOD(4-1,12)+1, 15), EDATE(DATE($A9 + INT((4-1)/12), MOD(4-1,12)+1, 15), -6)), 'Rate History'!$A$2:$C$10, 3, TRUE) -> 0 | G9: =VLOOKUP(IF($B$1, DATE($A9 + INT((5-1)/12), MOD(5-1,12)+1, 15), EDATE(DATE($A9 + INT((5-1)/12), MOD(5-1,12)+1, 15), -6)), 'Rate History'!$A$2:$C$10, 3, TRUE) -> 0 | H9: =VLOOKUP(IF($B$1, DATE($A9 + INT((6-1)/12), MOD(6-1,12)+1, 15), EDATE(DATE($A9 + INT((6-1)/12), MOD(6-1,12)+1, 15), -6)), 'Rate History'!$A$2:$C$10, 3, TRUE) -> 0 | I9: =VLOOKUP(IF($B$1, DATE($A9 + INT((7-1)/12), MOD(7-1,12)+1, 15), EDATE(DATE($A9 + INT((7-1)/12), MOD(7-1,12)+1, 15), -6)), 'Rate History'!$A$2:$C$10, 3, TRUE) -> 0 | J9: =VLOOKUP(IF($B$1, DATE($A9 + INT((8-1)/12), MOD(8-1,12)+1, 15), EDATE(DATE($A9 + INT((8-1)/12), MOD(8-1,12)+1, 15), -6)), 'Rate History'!$A$2:$C$10, 3, TRUE) -> 0 | K9: =VLOOKUP(IF($B$1, DATE($A9 + INT((9-1)/12), MOD(9-1,12)+1, 15), EDATE(DATE($A9 + INT((9-1)/12), MOD(9-1,12)+1, 15), -6)), 'Rate History'!$A$2:$C$10, 3, TRUE) -> 0 | L9: =VLOOKUP(IF($B$1, DATE($A9 + INT((10-1)/12), MOD(10-1,12)+1, 15), EDATE(DATE($A9 + INT((10-1)/12), MOD(10-1,12)+1, 15), -6)), 'Rate History'!$A$2:$C$10, 3, TRUE) -> 0 | M9: =VLOOKUP(IF($B$1, DATE($A9 + INT((11-1)/12), MOD(11-1,12)+1, 15), EDATE(DATE($A9 + INT((11-1)/12), MOD(11-1,12)+1, 15), -6)), 'Rate History'!$A$2:$C$10, 3, TRUE) -> 0 | N9: =VLOOKUP(IF($B$1, DATE($A9 + INT((12-1)/12), MOD(12-1,12)+1, 15), EDATE(DATE($A9 + INT((12-1)/12), MOD(12-1,12)+1, 15), -6)), 'Rate History'!$A$2:$C$10, 3, TRUE) -> 0 | O9: =VLOOKUP(IF($B$1, DATE($A9 + INT((13-1)/12), MOD(13-1,12)+1, 15), EDATE(DATE($A9 + INT((13-1)/12), MOD(13-1,12)+1, 15), -6)), 'Rate History'!$A$2:$C$10, 3, TRUE) -> 0 | P9: =VLOOKUP(IF($B$1, DATE($A9 + INT((14-1)/12), MOD(14-1,12)+1, 15), EDATE(DATE($A9 + INT((14-1)/12), MOD(14-1,12)+1, 15), -6)), 'Rate History'!$A$2:$C$10, 3, TRUE) -> 0 | Q9: =VLOOKUP(IF($B$1, DATE($A9 + INT((15-1)/12), MOD(15-1,12)+1, 15), EDATE(DATE($A9 + INT((15-1)/12), MOD(15-1,12)+1, 15), -6)), 'Rate History'!$A$2:$C$10, 3, TRUE) -> 0 | R9: =VLOOKUP(IF($B$1, DATE($A9 + INT((16-1)/12), MOD(16-1,12)+1, 15), EDATE(DATE($A9 + INT((16-1)/12), MOD(16-1,12)+1, 15), -6)), 'Rate History'!$A$2:$C$10, 3, TRUE) -> 0 | S9: =VLOOKUP(IF($B$1, DATE($A9 + INT((17-1)/12), MOD(17-1,12)+1, 15), EDATE(DATE($A9 + INT((17-1)/12), MOD(17-1,12)+1, 15), -6)), 'Rate History'!$A$2:$C$10, 3, TRUE) -> 0 | T9: =VLOOKUP(IF($B$1, DATE($A9 + INT((18-1)/12), MOD(18-1,12)+1, 15), EDATE(DATE($A9 + INT((18-1)/12), MOD(18-1,12)+1, 15), -6)), 'Rate History'!$A$2:$C$10, 3, TRUE) -> 0 | U9: =VLOOKUP(IF($B$1, DATE($A9 + INT((19-1)/12), MOD(19-1,12)+1, 15), EDATE(DATE($A9 + INT((19-1)/12), MOD(19-1,12)+1, 15), -6)), 'Rate History'!$A$2:$C$10, 3, TRUE) -> 0 | V9: =VLOOKUP(IF($B$1, DATE($A9 + INT((20-1)/12), MOD(20-1,12)+1, 15), EDATE(DATE($A9 + INT((20-1)/12), MOD(20-1,12)+1, 15), -6)), 'Rate History'!$A$2:$C$10, 3, TRUE) -> 0 | W9: =VLOOKUP(IF($B$1, DATE($A9 + INT((21-1)/12), MOD(21-1,12)+1, 15), EDATE(DATE($A9 + INT((21-1)/12), MOD(21-1,12)+1, 15), -6)), 'Rate History'!$A$2:$C$10, 3, TRUE) -> 0 | X9: =VLOOKUP(IF($B$1, DATE($A9 + INT((22-1)/12), MOD(22-1,12)+1, 15), EDATE(DATE($A9 + INT((22-1)/12), MOD(22-1,12)+1, 15), -6)), 'Rate History'!$A$2:$C$10, 3, TRUE) -> 0 | Y9: =VLOOKUP(IF($B$1, DATE($A9 + INT((23-1)/12), MOD(23-1,12)+1, 15), EDATE(DATE($A9 + INT((23-1)/12), MOD(23-1,12)+1, 15), -6)), 'Rate History'!$A$2:$C$10, 3, TRUE) -> 0 | Z9: =VLOOKUP(IF($B$1, DATE($A9 + INT((24-1)/12), MOD(24-1,12)+1, 15), EDATE(DATE($A9 + INT((24-1)/12), MOD(24-1,12)+1, 15), -6)), 'Rate History'!$A$2:$C$10, 3, TRUE) -> 0 | AA9: =SUMPRODUCT(C$4:Z$4, C9:Z9) -> 0 | AB9: ='Rate History'!$C$13 / AA9 -> 0 | AC9: =$B9 * AB9 -> 0
A10: 2020 | B10: 314643 | C10: =VLOOKUP(IF($B$1, DATE($A10 + INT((1-1)/12), MOD(1-1,12)+1, 15), EDATE(DATE($A10 + INT((1-1)/12), MOD(1-1,12)+1, 15), -6)), 'Rate History'!$A$2:$C$10, 3, TRUE) -> 0 | D10: =VLOOKUP(IF($B$1, DATE($A10 + INT((2-1)/12), MOD(2-1,12)+1, 15), EDATE(DATE($A10 + INT((2-1)/12), MOD(2-1,12)+1, 15), -6)), 'Rate History'!$A$2:$C$10, 3, TRUE) -> 0 | E10: =VLOOKUP(IF($B$1, DATE($A10 + INT((3-1)/12), MOD(3-1,12)+1, 15), EDATE(DATE($A10 + INT((3-1)/12), MOD(3-1,12)+1, 15), -6)), 'Rate History'!$A$2:$C$10, 3, TRUE) -> 0 | F10: =VLOOKUP(IF($B$1, DATE($A10 + INT((4-1)/12), MOD(4-1,12)+1, 15), EDATE(DATE($A10 + INT((4-1)/12), MOD(4-1,12)+1, 15), -6)), 'Rate History'!$A$2:$C$10, 3, TRUE) -> 0 | G10: =VLOOKUP(IF($B$1, DATE($A10 + INT((5-1)/12), MOD(5-1,12)+1, 15), EDATE(DATE($A10 + INT((5-1)/12), MOD(5-1,12)+1, 15), -6)), 'Rate History'!$A$2:$C$10, 3, TRUE) -> 0 | H10: =VLOOKUP(IF($B$1, DATE($A10 + INT((6-1)/12), MOD(6-1,12)+1, 15), EDATE(DATE($A10 + INT((6-1)/12), MOD(6-1,12)+1, 15), -6)), 'Rate History'!$A$2:$C$10, 3, TRUE) -> 0 | I10: =VLOOKUP(IF($B$1, DATE($A10 + INT((7-1)/12), MOD(7-1,12)+1, 15), EDATE(DATE($A10 + INT((7-1)/12), MOD(7-1,12)+1, 15), -6)), 'Rate History'!$A$2:$C$10, 3, TRUE) -> 0 | J10: =VLOOKUP(IF($B$1, DATE($A10 + INT((8-1)/12), MOD(8-1,12)+1, 15), EDATE(DATE($A10 + INT((8-1)/12), MOD(8-1,12)+1, 15), -6)), 'Rate History'!$A$2:$C$10, 3, TRUE) -> 0 | K10: =VLOOKUP(IF($B$1, DATE($A10 + INT((9-1)/12), MOD(9-1,12)+1, 15), EDATE(DATE($A10 + INT((9-1)/12), MOD(9-1,12)+1, 15), -6)), 'Rate History'!$A$2:$C$10, 3, TRUE) -> 0 | L10: =VLOOKUP(IF($B$1, DATE($A10 + INT((10-1)/12), MOD(10-1,12)+1, 15), EDATE(DATE($A10 + INT((10-1)/12), MOD(10-1,12)+1, 15), -6)), 'Rate History'!$A$2:$C$10, 3, TRUE) -> 0 | M10: =VLOOKUP(IF($B$1, DATE($A10 + INT((11-1)/12), MOD(11-1,12)+1, 15), EDATE(DATE($A10 + INT((11-1)/12), MOD(11-1,12)+1, 15), -6)), 'Rate History'!$A$2:$C$10, 3, TRUE) -> 0 | N10: =VLOOKUP(IF($B$1, DATE($A10 + INT((12-1)/12), MOD(12-1,12)+1, 15), EDATE(DATE($A10 + INT((12-1)/12), MOD(12-1,12)+1, 15), -6)), 'Rate History'!$A$2:$C$10, 3, TRUE) -> 0 | O10: =VLOOKUP(IF($B$1, DATE($A10 + INT((13-1)/12), MOD(13-1,12)+1, 15), EDATE(DATE($A10 + INT((13-1)/12), MOD(13-1,12)+1, 15), -6)), 'Rate History'!$A$2:$C$10, 3, TRUE) -> 0 | P10: =VLOOKUP(IF($B$1, DATE($A10 + INT((14-1)/12), MOD(14-1,12)+1, 15), EDATE(DATE($A10 + INT((14-1)/12), MOD(14-1,12)+1, 15), -6)), 'Rate History'!$A$2:$C$10, 3, TRUE) -> 0 | Q10: =VLOOKUP(IF($B$1, DATE($A10 + INT((15-1)/12), MOD(15-1,12)+1, 15), EDATE(DATE($A10 + INT((15-1)/12), MOD(15-1,12)+1, 15), -6)), 'Rate History'!$A$2:$C$10, 3, TRUE) -> 0 | R10: =VLOOKUP(IF($B$1, DATE($A10 + INT((16-1)/12), MOD(16-1,12)+1, 15), EDATE(DATE($A10 + INT((16-1)/12), MOD(16-1,12)+1, 15), -6)), 'Rate History'!$A$2:$C$10, 3, TRUE) -> 0 | S10: =VLOOKUP(IF($B$1, DATE($A10 + INT((17-1)/12), MOD(17-1,12)+1, 15), EDATE(DATE($A10 + INT((17-1)/12), MOD(17-1,12)+1, 15), -6)), 'Rate History'!$A$2:$C$10, 3, TRUE) -> 0 | T10: =VLOOKUP(IF($B$1, DATE($A10 + INT((18-1)/12), MOD(18-1,12)+1, 15), EDATE(DATE($A10 + INT((18-1)/12), MOD(18-1,12)+1, 15), -6)), 'Rate History'!$A$2:$C$10, 3, TRUE) -> 0 | U10: =VLOOKUP(IF($B$1, DATE($A10 + INT((19-1)/12), MOD(19-1,12)+1, 15), EDATE(DATE($A10 + INT((19-1)/12), MOD(19-1,12)+1, 15), -6)), 'Rate History'!$A$2:$C$10, 3, TRUE) -> 0 | V10: =VLOOKUP(IF($B$1, DATE($A10 + INT((20-1)/12), MOD(20-1,12)+1, 15), EDATE(DATE($A10 + INT((20-1)/12), MOD(20-1,12)+1, 15), -6)), 'Rate History'!$A$2:$C$10, 3, TRUE) -> 0 | W10: =VLOOKUP(IF($B$1, DATE($A10 + INT((21-1)/12), MOD(21-1,12)+1, 15), EDATE(DATE($A10 + INT((21-1)/12), MOD(21-1,12)+1, 15), -6)), 'Rate History'!$A$2:$C$10, 3, TRUE) -> 0 | X10: =VLOOKUP(IF($B$1, DATE($A10 + INT((22-1)/12), MOD(22-1,12)+1, 15), EDATE(DATE($A10 + INT((22-1)/12), MOD(22-1,12)+1, 15), -6)), 'Rate History'!$A$2:$C$10, 3, TRUE) -> 0 | Y10: =VLOOKUP(IF($B$1, DATE($A10 + INT((23-1)/12), MOD(23-1,12)+1, 15), EDATE(DATE($A10 + INT((23-1)/12), MOD(23-1,12)+1, 15), -6)), 'Rate History'!$A$2:$C$10, 3, TRUE) -> 0 | Z10: =VLOOKUP(IF($B$1, DATE($A10 + INT((24-1)/12), MOD(24-1,12)+1, 15), EDATE(DATE($A10 + INT((24-1)/12), MOD(24-1,12)+1, 15), -6)), 'Rate History'!$A$2:$C$10, 3, TRUE) -> 0 | AA10: =SUMPRODUCT(C$4:Z$4, C10:Z10) -> 0 | AB10: ='Rate History'!$C$13 / AA10 -> 0 | AC10: =$B10 * AB10 -> 0
A11: 2021 | B11: 484462 | C11: =VLOOKUP(IF($B$1, DATE($A11 + INT((1-1)/12), MOD(1-1,12)+1, 15), EDATE(DATE($A11 + INT((1-1)/12), MOD(1-1,12)+1, 15), -6)), 'Rate History'!$A$2:$C$10, 3, TRUE) -> 0 | D11: =VLOOKUP(IF($B$1, DATE($A11 + INT((2-1)/12), MOD(2-1,12)+1, 15), EDATE(DATE($A11 + INT((2-1)/12), MOD(2-1,12)+1, 15), -6)), 'Rate History'!$A$2:$C$10, 3, TRUE) -> 0 | E11: =VLOOKUP(IF($B$1, DATE($A11 + INT((3-1)/12), MOD(3-1,12)+1, 15), EDATE(DATE($A11 + INT((3-1)/12), MOD(3-1,12)+1, 15), -6)), 'Rate History'!$A$2:$C$10, 3, TRUE) -> 0 | F11: =VLOOKUP(IF($B$1, DATE($A11 + INT((4-1)/12), MOD(4-1,12)+1, 15), EDATE(DATE($A11 + INT((4-1)/12), MOD(4-1,12)+1, 15), -6)), 'Rate History'!$A$2:$C$10, 3, TRUE) -> 0 | G11: =VLOOKUP(IF($B$1, DATE($A11 + INT((5-1)/12), MOD(5-1,12)+1, 15), EDATE(DATE($A11 + INT((5-1)/12), MOD(5-1,12)+1, 15), -6)), 'Rate History'!$A$2:$C$10, 3, TRUE) -> 0 | H11: =VLOOKUP(IF($B$1, DATE($A11 + INT((6-1)/12), MOD(6-1,12)+1, 15), EDATE(DATE($A11 + INT((6-1)/12), MOD(6-1,12)+1, 15), -6)), 'Rate History'!$A$2:$C$10, 3, TRUE) -> 0 | I11: =VLOOKUP(IF($B$1, DATE($A11 + INT((7-1)/12), MOD(7-1,12)+1, 15), EDATE(DATE($A11 + INT((7-1)/12), MOD(7-1,12)+1, 15), -6)), 'Rate History'!$A$2:$C$10, 3, TRUE) -> 0 | J11: =VLOOKUP(IF($B$1, DATE($A11 + INT((8-1)/12), MOD(8-1,12)+1, 15), EDATE(DATE($A11 + INT((8-1)/12), MOD(8-1,12)+1, 15), -6)), 'Rate History'!$A$2:$C$10, 3, TRUE) -> 0 | K11: =VLOOKUP(IF($B$1, DATE($A11 + INT((9-1)/12), MOD(9-1,12)+1, 15), EDATE(DATE($A11 + INT((9-1)/12), MOD(9-1,12)+1, 15), -6)), 'Rate History'!$A$2:$C$10, 3, TRUE) -> 0 | L11: =VLOOKUP(IF($B$1, DATE($A11 + INT((10-1)/12), MOD(10-1,12)+1, 15), EDATE(DATE($A11 + INT((10-1)/12), MOD(10-1,12)+1, 15), -6)), 'Rate History'!$A$2:$C$10, 3, TRUE) -> 0 | M11: =VLOOKUP(IF($B$1, DATE($A11 + INT((11-1)/12), MOD(11-1,12)+1, 15), EDATE(DATE($A11 + INT((11-1)/12), MOD(11-1,12)+1, 15), -6)), 'Rate History'!$A$2:$C$10, 3, TRUE) -> 0 | N11: =VLOOKUP(IF($B$1, DATE($A11 + INT((12-1)/12), MOD(12-1,12)+1, 15), EDATE(DATE($A11 + INT((12-1)/12), MOD(12-1,12)+1, 15), -6)), 'Rate History'!$A$2:$C$10, 3, TRUE) -> 0 | O11: =VLOOKUP(IF($B$1, DATE($A11 + INT((13-1)/12), MOD(13-1,12)+1, 15), EDATE(DATE($A11 + INT((13-1)/12), MOD(13-1,12)+1, 15), -6)), 'Rate History'!$A$2:$C$10, 3, TRUE) -> 0 | P11: =VLOOKUP(IF($B$1, DATE($A11 + INT((14-1)/12), MOD(14-1,12)+1, 15), EDATE(DATE($A11 + INT((14-1)/12), MOD(14-1,12)+1, 15), -6)), 'Rate History'!$A$2:$C$10, 3, TRUE) -> 0 | Q11: =VLOOKUP(IF($B$1, DATE($A11 + INT((15-1)/12), MOD(15-1,12)+1, 15), EDATE(DATE($A11 + INT((15-1)/12), MOD(15-1,12)+1, 15), -6)), 'Rate History'!$A$2:$C$10, 3, TRUE) -> 0 | R11: =VLOOKUP(IF($B$1, DATE($A11 + INT((16-1)/12), MOD(16-1,12)+1, 15), EDATE(DATE($A11 + INT((16-1)/12), MOD(16-1,12)+1, 15), -6)), 'Rate History'!$A$2:$C$10, 3, TRUE) -> 0 | S11: =VLOOKUP(IF($B$1, DATE($A11 + INT((17-1)/12), MOD(17-1,12)+1, 15), EDATE(DATE($A11 + INT((17-1)/12), MOD(17-1,12)+1, 15), -6)), 'Rate History'!$A$2:$C$10, 3, TRUE) -> 0 | T11: =VLOOKUP(IF($B$1, DATE($A11 + INT((18-1)/12), MOD(18-1,12)+1, 15), EDATE(DATE($A11 + INT((18-1)/12), MOD(18-1,12)+1, 15), -6)), 'Rate History'!$A$2:$C$10, 3, TRUE) -> 0 | U11: =VLOOKUP(IF($B$1, DATE($A11 + INT((19-1)/12), MOD(19-1,12)+1, 15), EDATE(DATE($A11 + INT((19-1)/12), MOD(19-1,12)+1, 15), -6)), 'Rate History'!$A$2:$C$10, 3, TRUE) -> 0 | V11: =VLOOKUP(IF($B$1, DATE($A11 + INT((20-1)/12), MOD(20-1,12)+1, 15), EDATE(DATE($A11 + INT((20-1)/12), MOD(20-1,12)+1, 15), -6)), 'Rate History'!$A$2:$C$10, 3, TRUE) -> 0 | W11: =VLOOKUP(IF($B$1, DATE($A11 + INT((21-1)/12), MOD(21-1,12)+1, 15), EDATE(DATE($A11 + INT((21-1)/12), MOD(21-1,12)+1, 15), -6)), 'Rate History'!$A$2:$C$10, 3, TRUE) -> 0 | X11: =VLOOKUP(IF($B$1, DATE($A11 + INT((22-1)/12), MOD(22-1,12)+1, 15), EDATE(DATE($A11 + INT((22-1)/12), MOD(22-1,12)+1, 15), -6)), 'Rate History'!$A$2:$C$10, 3, TRUE) -> 0 | Y11: =VLOOKUP(IF($B$1, DATE($A11 + INT((23-1)/12), MOD(23-1,12)+1, 15), EDATE(DATE($A11 + INT((23-1)/12), MOD(23-1,12)+1, 15), -6)), 'Rate History'!$A$2:$C$10, 3, TRUE) -> 0 | Z11: =VLOOKUP(IF($B$1, DATE($A11 + INT((24-1)/12), MOD(24-1,12)+1, 15), EDATE(DATE($A11 + INT((24-1)/12), MOD(24-1,12)+1, 15), -6)), 'Rate History'!$A$2:$C$10, 3, TRUE) -> 0 | AA11: =SUMPRODUCT(C$4:Z$4, C11:Z11) -> 0 | AB11: ='Rate History'!$C$13 / AA11 -> 0 | AC11: =$B11 * AB11 -> 0
A12: 2022 | B12: 365106 | C12: =VLOOKUP(IF($B$1, DATE($A12 + INT((1-1)/12), MOD(1-1,12)+1, 15), EDATE(DATE($A12 + INT((1-1)/12), MOD(1-1,12)+1, 15), -6)), 'Rate History'!$A$2:$C$10, 3, TRUE) -> 0 | D12: =VLOOKUP(IF($B$1, DATE($A12 + INT((2-1)/12), MOD(2-1,12)+1, 15), EDATE(DATE($A12 + INT((2-1)/12), MOD(2-1,12)+1, 15), -6)), 'Rate History'!$A$2:$C$10, 3, TRUE) -> 0 | E12: =VLOOKUP(IF($B$1, DATE($A12 + INT((3-1)/12), MOD(3-1,12)+1, 15), EDATE(DATE($A12 + INT((3-1)/12), MOD(3-1,12)+1, 15), -6)), 'Rate History'!$A$2:$C$10, 3, TRUE) -> 0 | F12: =VLOOKUP(IF($B$1, DATE($A12 + INT((4-1)/12), MOD(4-1,12)+1, 15), EDATE(DATE($A12 + INT((4-1)/12), MOD(4-1,12)+1, 15), -6)), 'Rate History'!$A$2:$C$10, 3, TRUE) -> 0 | G12: =VLOOKUP(IF($B$1, DATE($A12 + INT((5-1)/12), MOD(5-1,12)+1, 15), EDATE(DATE($A12 + INT((5-1)/12), MOD(5-1,12)+1, 15), -6)), 'Rate History'!$A$2:$C$10, 3, TRUE) -> 0 | H12: =VLOOKUP(IF($B$1, DATE($A12 + INT((6-1)/12), MOD(6-1,12)+1, 15), EDATE(DATE($A12 + INT((6-1)/12), MOD(6-1,12)+1, 15), -6)), 'Rate History'!$A$2:$C$10, 3, TRUE) -> 0 | I12: =VLOOKUP(IF($B$1, DATE($A12 + INT((7-1)/12), MOD(7-1,12)+1, 15), EDATE(DATE($A12 + INT((7-1)/12), MOD(7-1,12)+1, 15), -6)), 'Rate History'!$A$2:$C$10, 3, TRUE) -> 0 | J12: =VLOOKUP(IF($B$1, DATE($A12 + INT((8-1)/12), MOD(8-1,12)+1, 15), EDATE(DATE($A12 + INT((8-1)/12), MOD(8-1,12)+1, 15), -6)), 'Rate History'!$A$2:$C$10, 3, TRUE) -> 0 | K12: =VLOOKUP(IF($B$1, DATE($A12 + INT((9-1)/12), MOD(9-1,12)+1, 15), EDATE(DATE($A12 + INT((9-1)/12), MOD(9-1,12)+1, 15), -6)), 'Rate History'!$A$2:$C$10, 3, TRUE) -> 0 | L12: =VLOOKUP(IF($B$1, DATE($A12 + INT((10-1)/12), MOD(10-1,12)+1, 15), EDATE(DATE($A12 + INT((10-1)/12), MOD(10-1,12)+1, 15), -6)), 'Rate History'!$A$2:$C$10, 3, TRUE) -> 0 | M12: =VLOOKUP(IF($B$1, DATE($A12 + INT((11-1)/12), MOD(11-1,12)+1, 15), EDATE(DATE($A12 + INT((11-1)/12), MOD(11-1,12)+1, 15), -6)), 'Rate History'!$A$2:$C$10, 3, TRUE) -> 0 | N12: =VLOOKUP(IF($B$1, DATE($A12 + INT((12-1)/12), MOD(12-1,12)+1, 15), EDATE(DATE($A12 + INT((12-1)/12), MOD(12-1,12)+1, 15), -6)), 'Rate History'!$A$2:$C$10, 3, TRUE) -> 0 | O12: =VLOOKUP(IF($B$1, DATE($A12 + INT((13-1)/12), MOD(13-1,12)+1, 15), EDATE(DATE($A12 + INT((13-1)/12), MOD(13-1,12)+1, 15), -6)), 'Rate History'!$A$2:$C$10, 3, TRUE) -> 0 | P12: =VLOOKUP(IF($B$1, DATE($A12 + INT((14-1)/12), MOD(14-1,12)+1, 15), EDATE(DATE($A12 + INT((14-1)/12), MOD(14-1,12)+1, 15), -6)), 'Rate History'!$A$2:$C$10, 3, TRUE) -> 0 | Q12: =VLOOKUP(IF($B$1, DATE($A12 + INT((15-1)/12), MOD(15-1,12)+1, 15), EDATE(DATE($A12 + INT((15-1)/12), MOD(15-1,12)+1, 15), -6)), 'Rate History'!$A$2:$C$10, 3, TRUE) -> 0 | R12: =VLOOKUP(IF($B$1, DATE($A12 + INT((16-1)/12), MOD(16-1,12)+1, 15), EDATE(DATE($A12 + INT((16-1)/12), MOD(16-1,12)+1, 15), -6)), 'Rate History'!$A$2:$C$10, 3, TRUE) -> 0 | S12: =VLOOKUP(IF($B$1, DATE($A12 + INT((17-1)/12), MOD(17-1,12)+1, 15), EDATE(DATE($A12 + INT((17-1)/12), MOD(17-1,12)+1, 15), -6)), 'Rate History'!$A$2:$C$10, 3, TRUE) -> 0 | T12: =VLOOKUP(IF($B$1, DATE($A12 + INT((18-1)/12), MOD(18-1,12)+1, 15), EDATE(DATE($A12 + INT((18-1)/12), MOD(18-1,12)+1, 15), -6)), 'Rate History'!$A$2:$C$10, 3, TRUE) -> 0 | U12: =VLOOKUP(IF($B$1, DATE($A12 + INT((19-1)/12), MOD(19-1,12)+1, 15), EDATE(DATE($A12 + INT((19-1)/12), MOD(19-1,12)+1, 15), -6)), 'Rate History'!$A$2:$C$10, 3, TRUE) -> 0 | V12: =VLOOKUP(IF($B$1, DATE($A12 + INT((20-1)/12), MOD(20-1,12)+1, 15), EDATE(DATE($A12 + INT((20-1)/12), MOD(20-1,12)+1, 15), -6)), 'Rate History'!$A$2:$C$10, 3, TRUE) -> 0 | W12: =VLOOKUP(IF($B$1, DATE($A12 + INT((21-1)/12), MOD(21-1,12)+1, 15), EDATE(DATE($A12 + INT((21-1)/12), MOD(21-1,12)+1, 15), -6)), 'Rate History'!$A$2:$C$10, 3, TRUE) -> 0 | X12: =VLOOKUP(IF($B$1, DATE($A12 + INT((22-1)/12), MOD(22-1,12)+1, 15), EDATE(DATE($A12 + INT((22-1)/12), MOD(22-1,12)+1, 15), -6)), 'Rate History'!$A$2:$C$10, 3, TRUE) -> 0 | Y12: =VLOOKUP(IF($B$1, DATE($A12 + INT((23-1)/12), MOD(23-1,12)+1, 15), EDATE(DATE($A12 + INT((23-1)/12), MOD(23-1,12)+1, 15), -6)), 'Rate History'!$A$2:$C$10, 3, TRUE) -> 0 | Z12: =VLOOKUP(IF($B$1, DATE($A12 + INT((24-1)/12), MOD(24-1,12)+1, 15), EDATE(DATE($A12 + INT((24-1)/12), MOD(24-1,12)+1, 15), -6)), 'Rate History'!$A$2:$C$10, 3, TRUE) -> 0 | AA12: =SUMPRODUCT(C$4:Z$4, C12:Z12) -> 0 | AB12: ='Rate History'!$C$13 / AA12 -> 0 | AC12: =$B12 * AB12 -> 0
A13: 2023 | B13: 208127 | C13: =VLOOKUP(IF($B$1, DATE($A13 + INT((1-1)/12), MOD(1-1,12)+1, 15), EDATE(DATE($A13 + INT((1-1)/12), MOD(1-1,12)+1, 15), -6)), 'Rate History'!$A$2:$C$10, 3, TRUE) -> 0 | D13: =VLOOKUP(IF($B$1, DATE($A13 + INT((2-1)/12), MOD(2-1,12)+1, 15), EDATE(DATE($A13 + INT((2-1)/12), MOD(2-1,12)+1, 15), -6)), 'Rate History'!$A$2:$C$10, 3, TRUE) -> 0 | E13: =VLOOKUP(IF($B$1, DATE($A13 + INT((3-1)/12), MOD(3-1,12)+1, 15), EDATE(DATE($A13 + INT((3-1)/12), MOD(3-1,12)+1, 15), -6)), 'Rate History'!$A$2:$C$10, 3, TRUE) -> 0 | F13: =VLOOKUP(IF($B$1, DATE($A13 + INT((4-1)/12), MOD(4-1,12)+1, 15), EDATE(DATE($A13 + INT((4-1)/12), MOD(4-1,12)+1, 15), -6)), 'Rate History'!$A$2:$C$10, 3, TRUE) -> 0 | G13: =VLOOKUP(IF($B$1, DATE($A13 + INT((5-1)/12), MOD(5-1,12)+1, 15), EDATE(DATE($A13 + INT((5-1)/12), MOD(5-1,12)+1, 15), -6)), 'Rate History'!$A$2:$C$10, 3, TRUE) -> 0 | H13: =VLOOKUP(IF($B$1, DATE($A13 + INT((6-1)/12), MOD(6-1,12)+1, 15), EDATE(DATE($A13 + INT((6-1)/12), MOD(6-1,12)+1, 15), -6)), 'Rate History'!$A$2:$C$10, 3, TRUE) -> 0 | I13: =VLOOKUP(IF($B$1, DATE($A13 + INT((7-1)/12), MOD(7-1,12)+1, 15), EDATE(DATE($A13 + INT((7-1)/12), MOD(7-1,12)+1, 15), -6)), 'Rate History'!$A$2:$C$10, 3, TRUE) -> 0 | J13: =VLOOKUP(IF($B$1, DATE($A13 + INT((8-1)/12), MOD(8-1,12)+1, 15), EDATE(DATE($A13 + INT((8-1)/12), MOD(8-1,12)+1, 15), -6)), 'Rate History'!$A$2:$C$10, 3, TRUE) -> 0 | K13: =VLOOKUP(IF($B$1, DATE($A13 + INT((9-1)/12), MOD(9-1,12)+1, 15), EDATE(DATE($A13 + INT((9-1)/12), MOD(9-1,12)+1, 15), -6)), 'Rate History'!$A$2:$C$10, 3, TRUE) -> 0 | L13: =VLOOKUP(IF($B$1, DATE($A13 + INT((10-1)/12), MOD(10-1,12)+1, 15), EDATE(DATE($A13 + INT((10-1)/12), MOD(10-1,12)+1, 15), -6)), 'Rate History'!$A$2:$C$10, 3, TRUE) -> 0 | M13: =VLOOKUP(IF($B$1, DATE($A13 + INT((11-1)/12), MOD(11-1,12)+1, 15), EDATE(DATE($A13 + INT((11-1)/12), MOD(11-1,12)+1, 15), -6)), 'Rate History'!$A$2:$C$10, 3, TRUE) -> 0 | N13: =VLOOKUP(IF($B$1, DATE($A13 + INT((12-1)/12), MOD(12-1,12)+1, 15), EDATE(DATE($A13 + INT((12-1)/12), MOD(12-1,12)+1, 15), -6)), 'Rate History'!$A$2:$C$10, 3, TRUE) -> 0 | O13: =VLOOKUP(IF($B$1, DATE($A13 + INT((13-1)/12), MOD(13-1,12)+1, 15), EDATE(DATE($A13 + INT((13-1)/12), MOD(13-1,12)+1, 15), -6)), 'Rate History'!$A$2:$C$10, 3, TRUE) -> 0 | P13: =VLOOKUP(IF($B$1, DATE($A13 + INT((14-1)/12), MOD(14-1,12)+1, 15), EDATE(DATE($A13 + INT((14-1)/12), MOD(14-1,12)+1, 15), -6)), 'Rate History'!$A$2:$C$10, 3, TRUE) -> 0 | Q13: =VLOOKUP(IF($B$1, DATE($A13 + INT((15-1)/12), MOD(15-1,12)+1, 15), EDATE(DATE($A13 + INT((15-1)/12), MOD(15-1,12)+1, 15), -6)), 'Rate History'!$A$2:$C$10, 3, TRUE) -> 0 | R13: =VLOOKUP(IF($B$1, DATE($A13 + INT((16-1)/12), MOD(16-1,12)+1, 15), EDATE(DATE($A13 + INT((16-1)/12), MOD(16-1,12)+1, 15), -6)), 'Rate History'!$A$2:$C$10, 3, TRUE) -> 0 | S13: =VLOOKUP(IF($B$1, DATE($A13 + INT((17-1)/12), MOD(17-1,12)+1, 15), EDATE(DATE($A13 + INT((17-1)/12), MOD(17-1,12)+1, 15), -6)), 'Rate History'!$A$2:$C$10, 3, TRUE) -> 0 | T13: =VLOOKUP(IF($B$1, DATE($A13 + INT((18-1)/12), MOD(18-1,12)+1, 15), EDATE(DATE($A13 + INT((18-1)/12), MOD(18-1,12)+1, 15), -6)), 'Rate History'!$A$2:$C$10, 3, TRUE) -> 0 | U13: =VLOOKUP(IF($B$1, DATE($A13 + INT((19-1)/12), MOD(19-1,12)+1, 15), EDATE(DATE($A13 + INT((19-1)/12), MOD(19-1,12)+1, 15), -6)), 'Rate History'!$A$2:$C$10, 3, TRUE) -> 0 | V13: =VLOOKUP(IF($B$1, DATE($A13 + INT((20-1)/12), MOD(20-1,12)+1, 15), EDATE(DATE($A13 + INT((20-1)/12), MOD(20-1,12)+1, 15), -6)), 'Rate History'!$A$2:$C$10, 3, TRUE) -> 0 | W13: =VLOOKUP(IF($B$1, DATE($A13 + INT((21-1)/12), MOD(21-1,12)+1, 15), EDATE(DATE($A13 + INT((21-1)/12), MOD(21-1,12)+1, 15), -6)), 'Rate History'!$A$2:$C$10, 3, TRUE) -> 0 | X13: =VLOOKUP(IF($B$1, DATE($A13 + INT((22-1)/12), MOD(22-1,12)+1, 15), EDATE(DATE($A13 + INT((22-1)/12), MOD(22-1,12)+1, 15), -6)), 'Rate History'!$A$2:$C$10, 3, TRUE) -> 0 | Y13: =VLOOKUP(IF($B$1, DATE($A13 + INT((23-1)/12), MOD(23-1,12)+1, 15), EDATE(DATE($A13 + INT((23-1)/12), MOD(23-1,12)+1, 15), -6)), 'Rate History'!$A$2:$C$10, 3, TRUE) -> 0 | Z13: =VLOOKUP(IF($B$1, DATE($A13 + INT((24-1)/12), MOD(24-1,12)+1, 15), EDATE(DATE($A13 + INT((24-1)/12), MOD(24-1,12)+1, 15), -6)), 'Rate History'!$A$2:$C$10, 3, TRUE) -> 0 | AA13: =SUMPRODUCT(C$4:Z$4, C13:Z13) -> 0 | AB13: ='Rate History'!$C$13 / AA13 -> 0 | AC13: =$B13 * AB13 -> 0
