Workbook

Sheet 1_Rate_Changes
A1: Effective Date | B1: Rate Change % | C1: Cumulative Level
A2: 44562 | B2: 0 | C2: 1
A3: 44927 | B3: 0.05 | C3: =C2*(1+B3) -> 0
A4: 45474 | B4: 0.1 | C4: =C3*(1+B4) -> 0

Sheet 2_Policy_Level (engine)
A1: Input | B1: Value
A2: Historical Premium | B2: 1000
A3: Policy Effective Date | B3: 45047
A4: Evaluation Date | B4: 45658
A5: Policy Term (months) | B5: 12
A7: Written Factor Logic
A8: Current Level | B8: =VLOOKUP(B4, '1_Rate_Changes'!$A$2:$C$100, 3, TRUE) -> 0
A9: Historical Level | B9: =VLOOKUP(B3, '1_Rate_Changes'!$A$2:$C$100, 3, TRUE) -> 0
A10: Written Factor (Cur/Hist) | B10: =B8/B9 -> 0
A12: Earned Factor Logic
A13: Assuming N periods (term_months)
A14: Period | B14: Mid-Date Formula (Info) | C14: Mid-Date (Eval) | D14: Rate Level | E14: Weight
A15: 1 | B15: =INT($B$3 + ((1-0.5)/$B$5)*($B$5*30.4375)) | C15: =INT($B$3 + ((1-0.5)/$B$5)*($B$5*30.4375)) -> 0 | D15: =VLOOKUP(C15, '1_Rate_Changes'!$A$2:$C$100, 3, TRUE) -> 0 | E15: 0.083333333
A16: 2 | B16: =INT($B$3 + ((2-0.5)/$B$5)*($B$5*30.4375)) | C16: =INT($B$3 + ((2-0.5)/$B$5)*($B$5*30.4375)) -> 0 | D16: =VLOOKUP(C16, '1_Rate_Changes'!$A$2:$C$100, 3, TRUE) -> 0 | E16: 0.083333333
A17: 3 | B17: =INT($B$3 + ((3-0.5)/$B$5)*($B$5*30.4375)) | C17: =INT($B$3 + ((3-0.5)/$B$5)*($B$5*30.4375)) -> 0 | D17: =VLOOKUP(C17, '1_Rate_Changes'!$A$2:$C$100, 3, TRUE) -> 0 | E17: 0.083333333
A18: 4 | B18: =INT($B$3 + ((4-0.5)/$B$5)*($B$5*30.4375)) | C18: =INT($B$3 + ((4-0.5)/$B$5)*($B$5*30.4375)) -> 0 | D18: =VLOOKUP(C18, '1_Rate_Changes'!$A$2:$C$100, 3, TRUE) -> 0 | E18: 0.083333333
A19: 5 | B19: =INT($B$3 + ((5-0.5)/$B$5)*($B$5*30.4375)) | C19: =INT($B$3 + ((5-0.5)/$B$5)*($B$5*30.4375)) -> 0 | D19: =VLOOKUP(C19, '1_Rate_Changes'!$A$2:$C$100, 3, TRUE) -> 0 | E19: 0.083333333
A20: 6 | B20: =INT($B$3 + ((6-0.5)/$B$5)*($B$5*30.4375)) | C20: =INT($B$3 + ((6-0.5)/$B$5)*($B$5*30.4375)) -> 0 | D20: =VLOOKUP(C20, '1_Rate_Changes'!$A$2:$C$100, 3, TRUE) -> 0 | E20: 0.083333333
A21: 7 | B21: =INT($B$3 + ((7-0.5)/$B$5)*($B$5*30.4375)) | C21: =INT($B$3 + ((7-0.5)/$B$5)*($B$5*30.4375)) -> 0 | D21: =VLOOKUP(C21, '1_Rate_Changes'!$A$2:$C$100, 3, TRUE) -> 0 | E21: 0.083333333
A22: 8 | B22: =INT($B$3 + ((8-0.5)/$B$5)*($B$5*30.4375)) | C22: =INT($B$3 + ((8-0.5)/$B$5)*($B$5*30.4375)) -> 0 | D22: =VLOOKUP(C22, '1_Rate_Changes'!$A$2:$C$100, 3, TRUE) -> 0 | E22: 0.083333333
A23: 9 | B23: =INT($B$3 + ((9-0.5)/$B$5)*($B$5*30.4375)) | C23: =INT($B$3 + ((9-0.5)/$B$5)*($B$5*30.4375)) -> 0 | D23: =VLOOKUP(C23, '1_Rate_Changes'!$A$2:$C$100, 3, TRUE) -> 0 | E23: 0.083333333
A24: 10 | B24: =INT($B$3 + ((10-0.5)/$B$5)*($B$5*30.4375)) | C24: =INT($B$3 + ((10-0.5)/$B$5)*($B$5*30.4375)) -> 0 | D24: =VLOOKUP(C24, '1_Rate_Changes'!$A$2:$C$100, 3, TRUE) -> 0 | E24: 0.083333333
A25: 11 | B25: =INT($B$3 + ((11-0.5)/$B$5)*($B$5*30.4375)) | C25: =INT($B$3 + ((11-0.5)/$B$5)*($B$5*30.4375)) -> 0 | D25: =VLOOKUP(C25, '1_Rate_Changes'!$A$2:$C$100, 3, TRUE) -> 0 | E25: 0.083333333
A26: 12 | B26: =INT($B$3 + ((12-0.5)/$B$5)*($B$5*30.4375)) | C26: =INT($B$3 + ((12-0.5)/$B$5)*($B$5*30.4375)) -> 0 | D26: =VLOOKUP(C26, '1_Rate_Changes'!$A$2:$C$100, 3, TRUE) -> 0 | E26: 0.083333333
C27: Weighted Hist Level: | D27: =SUMPRODUCT(D15:D26, E15:E26) -> 0
C28: Earned Factor (Cur/W.Hist): | D28: =$B$8/D27 -> 0

Sheet 3_Aggregated (parallel)
A1: Input | B1: Value | G1: CY EP Factor - 50x50 Integration (parallelogram.py)
A2: Evaluation Date | B2: 45658 | G2: Point i | H2: Point j | I2: t_date (t) | J2: eff_date | K2: Rate Level
A3: Calendar/Policy Year | B3: 2023 | G3: 0 | H3: 0 | I3: =INT(DATE($B$3,1,1) + (0+0.5)*365/50) -> 0 | J3: =I3 - INT(ROUND($B$4 * 30.4375, 0) * (0+0.5)/50) -> 0 | K3: =VLOOKUP(J3, '1_Rate_Changes'!$A$2:$C$100, 3, TRUE) -> 0
A4: Policy Term (months) | B4: 12 | G4: 0 | H4: 1 | I4: =INT(DATE($B$3,1,1) + (0+0.5)*365/50) -> 0 | J4: =I4 - INT(ROUND($B$4 * 30.4375, 0) * (1+0.5)/50) -> 0 | K4: =VLOOKUP(J4, '1_Rate_Changes'!$A$2:$C$100, 3, TRUE) -> 0
A5: Current Rate Level | B5: =VLOOKUP(B2, '1_Rate_Changes'!$A$2:$C$100, 3, TRUE) -> 0 | G5: 0 | H5: 2 | I5: =INT(DATE($B$3,1,1) + (0+0.5)*365/50) -> 0 | J5: =I5 - INT(ROUND($B$4 * 30.4375, 0) * (2+0.5)/50) -> 0 | K5: =VLOOKUP(J5, '1_Rate_Changes'!$A$2:$C$100, 3, TRUE) -> 0
G6: 0 | H6: 3 | I6: =INT(DATE($B$3,1,1) + (0+0.5)*365/50) -> 0 | J6: =I6 - INT(ROUND($B$4 * 30.4375, 0) * (3+0.5)/50) -> 0 | K6: =VLOOKUP(J6, '1_Rate_Changes'!$A$2:$C$100, 3, TRUE) -> 0
A7: WP Factor Logic | G7: 0 | H7: 4 | I7: =INT(DATE($B$3,1,1) + (0+0.5)*365/50) -> 0 | J7: =I7 - INT(ROUND($B$4 * 30.4375, 0) * (4+0.5)/50) -> 0 | K7: =VLOOKUP(J7, '1_Rate_Changes'!$A$2:$C$100, 3, TRUE) -> 0
A8: Avg Eff Date (July 1st) | B8: =DATE(B3, 7, 1) -> 0 | G8: 0 | H8: 5 | I8: =INT(DATE($B$3,1,1) + (0+0.5)*365/50) -> 0 | J8: =I8 - INT(ROUND($B$4 * 30.4375, 0) * (5+0.5)/50) -> 0 | K8: =VLOOKUP(J8, '1_Rate_Changes'!$A$2:$C$100, 3, TRUE) -> 0
A9: Rate Level | B9: =VLOOKUP(B8, '1_Rate_Changes'!$A$2:$C$100, 3, TRUE) -> 0 | G9: 0 | H9: 6 | I9: =INT(DATE($B$3,1,1) + (0+0.5)*365/50) -> 0 | J9: =I9 - INT(ROUND($B$4 * 30.4375, 0) * (6+0.5)/50) -> 0 | K9: =VLOOKUP(J9, '1_Rate_Changes'!$A$2:$C$100, 3, TRUE) -> 0
A10: WP Factor | B10: =B5/B9 -> 0 | G10: 0 | H10: 7 | I10: =INT(DATE($B$3,1,1) + (0+0.5)*365/50) -> 0 | J10: =I10 - INT(ROUND($B$4 * 30.4375, 0) * (7+0.5)/50) -> 0 | K10: =VLOOKUP(J10, '1_Rate_Changes'!$A$2:$C$100, 3, TRUE) -> 0
G11: 0 | H11: 8 | I11: =INT(DATE($B$3,1,1) + (0+0.5)*365/50) -> 0 | J11: =I11 - INT(ROUND($B$4 * 30.4375, 0) * (8+0.5)/50) -> 0 | K11: =VLOOKUP(J11, '1_Rate_Changes'!$A$2:$C$100, 3, TRUE) -> 0
A12: PY EP Factor Logic | G12: 0 | H12: 9 | I12: =INT(DATE($B$3,1,1) + (0+0.5)*365/50) -> 0 | J12: =I12 - INT(ROUND($B$4 * 30.4375, 0) * (9+0.5)/50) -> 0 | K12: =VLOOKUP(J12, '1_Rate_Changes'!$A$2:$C$100, 3, TRUE) -> 0
A13: Month (m) | B13: Calc Midpoint | C13: Eff Date (-term/2) | D13: Rate Level | E13: Weight(w) | G13: 0 | H13: 10 | I13: =INT(DATE($B$3,1,1) + (0+0.5)*365/50) -> 0 | J13: =I13 - INT(ROUND($B$4 * 30.4375, 0) * (10+0.5)/50) -> 0 | K13: =VLOOKUP(J13, '1_Rate_Changes'!$A$2:$C$100, 3, TRUE) -> 0
A14: 1 | B14: =DATE($B$3 + INT((1-1)/12), MOD(1-1, 12) + 1, 15) -> 0 | C14: =EDATE(B14, -(INT($B$4/2))) -> 0 | D14: =VLOOKUP(C14, '1_Rate_Changes'!$A$2:$C$100, 3, TRUE) -> 0 | E14: =IF(1<=$B$4, 1, (2*$B$4)-1+1) -> 0 | G14: 0 | H14: 11 | I14: =INT(DATE($B$3,1,1) + (0+0.5)*365/50) -> 0 | J14: =I14 - INT(ROUND($B$4 * 30.4375, 0) * (11+0.5)/50) -> 0 | K14: =VLOOKUP(J14, '1_Rate_Changes'!$A$2:$C$100, 3, TRUE) -> 0
A15: 2 | B15: =DATE($B$3 + INT((2-1)/12), MOD(2-1, 12) + 1, 15) -> 0 | C15: =EDATE(B15, -(INT($B$4/2))) -> 0 | D15: =VLOOKUP(C15, '1_Rate_Changes'!$A$2:$C$100, 3, TRUE) -> 0 | E15: =IF(2<=$B$4, 2, (2*$B$4)-2+1) -> 0 | G15: 0 | H15: 12 | I15: =INT(DATE($B$3,1,1) + (0+0.5)*365/50) -> 0 | J15: =I15 - INT(ROUND($B$4 * 30.4375, 0) * (12+0.5)/50) -> 0 | K15: =VLOOKUP(J15, '1_Rate_Changes'!$A$2:$C$100, 3, TRUE) -> 0
A16: 3 | B16: =DATE($B$3 + INT((3-1)/12), MOD(3-1, 12) + 1, 15) -> 0 | C16: =EDATE(B16, -(INT($B$4/2))) -> 0 | D16: =VLOOKUP(C16, '1_Rate_Changes'!$A$2:$C$100, 3, TRUE) -> 0 | E16: =IF(3<=$B$4, 3, (2*$B$4)-3+1) -> 0 | G16: 0 | H16: 13 | I16: =INT(DATE($B$3,1,1) + (0+0.5)*365/50) -> 0 | J16: =I16 - INT(ROUND($B$4 * 30.4375, 0) * (13+0.5)/50) -> 0 | K16: =VLOOKUP(J16, '1_Rate_Changes'!$A$2:$C$100, 3, TRUE) -> 0
A17: 4 | B17: =DATE($B$3 + INT((4-1)/12), MOD(4-1, 12) + 1, 15) -> 0 | C17: =EDATE(B17, -(INT($B$4/2))) -> 0 | D17: =VLOOKUP(C17, '1_Rate_Changes'!$A$2:$C$100, 3, TRUE) -> 0 | E17: =IF(4<=$B$4, 4, (2*$B$4)-4+1) -> 0 | G17: 0 | H17: 14 | I17: =INT(DATE($B$3,1,1) + (0+0.5)*365/50) -> 0 | J17: =I17 - INT(ROUND($B$4 * 30.4375, 0) * (14+0.5)/50) -> 0 | K17: =VLOOKUP(J17, '1_Rate_Changes'!$A$2:$C$100, 3, TRUE) -> 0
A18: 5 | B18: =DATE($B$3 + INT((5-1)/12), MOD(5-1, 12) + 1, 15) -> 0 | C18: =EDATE(B18, -(INT($B$4/2))) -> 0 | D18: =VLOOKUP(C18, '1_Rate_Changes'!$A$2:$C$100, 3, TRUE) -> 0 | E18: =IF(5<=$B$4, 5, (2*$B$4)-5+1) -> 0 | G18: 0 | H18: 15 | I18: =INT(DATE($B$3,1,1) + (0+0.5)*365/50) -> 0 | J18: =I18 - INT(ROUND($B$4 * 30.4375, 0) * (15+0.5)/50) -> 0 | K18: =VLOOKUP(J18, '1_Rate_Changes'!$A$2:$C$100, 3, TRUE) -> 0
A19: 6 | B19: =DATE($B$3 + INT((6-1)/12), MOD(6-1, 12) + 1, 15) -> 0 | C19: =EDATE(B19, -(INT($B$4/2))) -> 0 | D19: =VLOOKUP(C19, '1_Rate_Changes'!$A$2:$C$100, 3, TRUE) -> 0 | E19: =IF(6<=$B$4, 6, (2*$B$4)-6+1) -> 0 | G19: 0 | H19: 16 | I19: =INT(DATE($B$3,1,1) + (0+0.5)*365/50) -> 0 | J19: =I19 - INT(ROUND($B$4 * 30.4375, 0) * (16+0.5)/50) -> 0 | K19: =VLOOKUP(J19, '1_Rate_Changes'!$A$2:$C$100, 3, TRUE) -> 0
A20: 7 | B20: =DATE($B$3 + INT((7-1)/12), MOD(7-1, 12) + 1, 15) -> 0 | C20: =EDATE(B20, -(INT($B$4/2))) -> 0 | D20: =VLOOKUP(C20, '1_Rate_Changes'!$A$2:$C$100, 3, TRUE) -> 0 | E20: =IF(7<=$B$4, 7, (2*$B$4)-7+1) -> 0 | G20: 0 | H20: 17 | I20: =INT(DATE($B$3,1,1) + (0+0.5)*365/50) -> 0 | J20: =I20 - INT(ROUND($B$4 * 30.4375, 0) * (17+0.5)/50) -> 0 | K20: =VLOOKUP(J20, '1_Rate_Changes'!$A$2:$C$100, 3, TRUE) -> 0
A21: 8 | B21: =DATE($B$3 + INT((8-1)/12), MOD(8-1, 12) + 1, 15) -> 0 | C21: =EDATE(B21, -(INT($B$4/2))) -> 0 | D21: =VLOOKUP(C21, '1_Rate_Changes'!$A$2:$C$100, 3, TRUE) -> 0 | E21: =IF(8<=$B$4, 8, (2*$B$4)-8+1) -> 0 | G21: 0 | H21: 18 | I21: =INT(DATE($B$3,1,1) + (0+0.5)*365/50) -> 0 | J21: =I21 - INT(ROUND($B$4 * 30.4375, 0) * (18+0.5)/50) -> 0 | K21: =VLOOKUP(J21, '1_Rate_Changes'!$A$2:$C$100, 3, TRUE) -> 0
A22: 9 | B22: =DATE($B$3 + INT((9-1)/12), MOD(9-1, 12) + 1, 15) -> 0 | C22: =EDATE(B22, -(INT($B$4/2))) -> 0 | D22: =VLOOKUP(C22, '1_Rate_Changes'!$A$2:$C$100, 3, TRUE) -> 0 | E22: =IF(9<=$B$4, 9, (2*$B$4)-9+1) -> 0 | G22: 0 | H22: 19 | I22: =INT(DATE($B$3,1,1) + (0+0.5)*365/50) -> 0 | J22: =I22 - INT(ROUND($B$4 * 30.4375, 0) * (19+0.5)/50) -> 0 | K22: =VLOOKUP(J22, '1_Rate_Changes'!$A$2:$C$100, 3, TRUE) -> 0
A23: 10 | B23: =DATE($B$3 + INT((10-1)/12), MOD(10-1, 12) + 1, 15) -> 0 | C23: =EDATE(B23, -(INT($B$4/2))) -> 0 | D23: =VLOOKUP(C23, '1_Rate_Changes'!$A$2:$C$100, 3, TRUE) -> 0 | E23: =IF(10<=$B$4, 10, (2*$B$4)-10+1) -> 0 | G23: 0 | H23: 20 | I23: =INT(DATE($B$3,1,1) + (0+0.5)*365/50) -> 0 | J23: =I23 - INT(ROUND($B$4 * 30.4375, 0) * (20+0.5)/50) -> 0 | K23: =VLOOKUP(J23, '1_Rate_Changes'!$A$2:$C$100, 3, TRUE) -> 0
A24: 11 | B24: =DATE($B$3 + INT((11-1)/12), MOD(11-1, 12) + 1, 15) -> 0 | C24: =EDATE(B24, -(INT($B$4/2))) -> 0 | D24: =VLOOKUP(C24, '1_Rate_Changes'!$A$2:$C$100, 3, TRUE) -> 0 | E24: =IF(11<=$B$4, 11, (2*$B$4)-11+1) -> 0 | G24: 0 | H24: 21 | I24: =INT(DATE($B$3,1,1) + (0+0.5)*365/50) -> 0 | J24: =I24 - INT(ROUND($B$4 * 30.4375, 0) * (21+0.5)/50) -> 0 | K24: =VLOOKUP(J24, '1_Rate_Changes'!$A$2:$C$100, 3, TRUE) -> 0
A25: 12 | B25: =DATE($B$3 + INT((12-1)/12), MOD(12-1, 12) + 1, 15) -> 0 | C25: =EDATE(B25, -(INT($B$4/2))) -> 0 | D25: =VLOOKUP(C25, '1_Rate_Changes'!$A$2:$C$100, 3, TRUE) -> 0 | E25: =IF(12<=$B$4, 12, (2*$B$4)-12+1) -> 0 | G25: 0 | H25: 22 | I25: =INT(DATE($B$3,1,1) + (0+0.5)*365/50) -> 0 | J25: =I25 - INT(ROUND($B$4 * 30.4375, 0) * (22+0.5)/50) -> 0 | K25: =VLOOKUP(J25, '1_Rate_Changes'!$A$2:$C$100, 3, TRUE) -> 0
A26: 13 | B26: =DATE($B$3 + INT((13-1)/12), MOD(13-1, 12) + 1, 15) -> 0 | C26: =EDATE(B26, -(INT($B$4/2))) -> 0 | D26: =VLOOKUP(C26, '1_Rate_Changes'!$A$2:$C$100, 3, TRUE) -> 0 | E26: =IF(13<=$B$4, 13, (2*$B$4)-13+1) -> 0 | G26: 0 | H26: 23 | I26: =INT(DATE($B$3,1,1) + (0+0.5)*365/50) -> 0 | J26: =I26 - INT(ROUND($B$4 * 30.4375, 0) * (23+0.5)/50) -> 0 | K26: =VLOOKUP(J26, '1_Rate_Changes'!$A$2:$C$100, 3, TRUE) -> 0
A27: 14 | B27: =DATE($B$3 + INT((14-1)/12), MOD(14-1, 12) + 1, 15) -> 0 | C27: =EDATE(B27, -(INT($B$4/2))) -> 0 | D27: =VLOOKUP(C27, '1_Rate_Changes'!$A$2:$C$100, 3, TRUE) -> 0 | E27: =IF(14<=$B$4, 14, (2*$B$4)-14+1) -> 0 | G27: 0 | H27: 24 | I27: =INT(DATE($B$3,1,1) + (0+0.5)*365/50) -> 0 | J27: =I27 - INT(ROUND($B$4 * 30.4375, 0) * (24+0.5)/50) -> 0 | K27: =VLOOKUP(J27, '1_Rate_Changes'!$A$2:$C$100, 3, TRUE) -> 0
A28: 15 | B28: =DATE($B$3 + INT((15-1)/12), MOD(15-1, 12) + 1, 15) -> 0 | C28: =EDATE(B28, -(INT($B$4/2))) -> 0 | D28: =VLOOKUP(C28, '1_Rate_Changes'!$A$2:$C$100, 3, TRUE) -> 0 | E28: =IF(15<=$B$4, 15, (2*$B$4)-15+1) -> 0 | G28: 0 | H28: 25 | I28: =INT(DATE($B$3,1,1) + (0+0.5)*365/50) -> 0 | J28: =I28 - INT(ROUND($B$4 * 30.4375, 0) * (25+0.5)/50) -> 0 | K28: =VLOOKUP(J28, '1_Rate_Changes'!$A$2:$C$100, 3, TRUE) -> 0
A29: 16 | B29: =DATE($B$3 + INT((16-1)/12), MOD(16-1, 12) + 1, 15) -> 0 | C29: =EDATE(B29, -(INT($B$4/2))) -> 0 | D29: =VLOOKUP(C29, '1_Rate_Changes'!$A$2:$C$100, 3, TRUE) -> 0 | E29: =IF(16<=$B$4, 16, (2*$B$4)-16+1) -> 0 | G29: 0 | H29: 26 | I29: =INT(DATE($B$3,1,1) + (0+0.5)*365/50) -> 0 | J29: =I29 - INT(ROUND($B$4 * 30.4375, 0) * (26+0.5)/50) -> 0 | K29: =VLOOKUP(J29, '1_Rate_Changes'!$A$2:$C$100, 3, TRUE) -> 0
A30: 17 | B30: =DATE($B$3 + INT((17-1)/12), MOD(17-1, 12) + 1, 15) -> 0 | C30: =EDATE(B30, -(INT($B$4/2))) -> 0 | D30: =VLOOKUP(C30, '1_Rate_Changes'!$A$2:$C$100, 3, TRUE) -> 0 | E30: =IF(17<=$B$4, 17, (2*$B$4)-17+1) -> 0 | G30: 0 | H30: 27 | I30: =INT(DATE($B$3,1,1) + (0+0.5)*365/50) -> 0 | J30: =I30 - INT(ROUND($B$4 * 30.4375, 0) * (27+0.5)/50) -> 0 | K30: =VLOOKUP(J30, '1_Rate_Changes'!$A$2:$C$100, 3, TRUE) -> 0
A31: 18 | B31: =DATE($B$3 + INT((18-1)/12), MOD(18-1, 12) + 1, 15) -> 0 | C31: =EDATE(B31, -(INT($B$4/2))) -> 0 | D31: =VLOOKUP(C31, '1_Rate_Changes'!$A$2:$C$100, 3, TRUE) -> 0 | E31: =IF(18<=$B$4, 18, (2*$B$4)-18+1) -> 0 | G31: 0 | H31: 28 | I31: =INT(DATE($B$3,1,1) + (0+0.5)*365/50) -> 0 | J31: =I31 - INT(ROUND($B$4 * 30.4375, 0) * (28+0.5)/50) -> 0 | K31: =VLOOKUP(J31, '1_Rate_Changes'!$A$2:$C$100, 3, TRUE) -> 0
A32: 19 | B32: =DATE($B$3 + INT((19-1)/12), MOD(19-1, 12) + 1, 15) -> 0 | C32: =EDATE(B32, -(INT($B$4/2))) -> 0 | D32: =VLOOKUP(C32, '1_Rate_Changes'!$A$2:$C$100, 3, TRUE) -> 0 | E32: =IF(19<=$B$4, 19, (2*$B$4)-19+1) -> 0 | G32: 0 | H32: 29 | I32: =INT(DATE($B$3,1,1) + (0+0.5)*365/50) -> 0 | J32: =I32 - INT(ROUND($B$4 * 30.4375, 0) * (29+0.5)/50) -> 0 | K32: =VLOOKUP(J32, '1_Rate_Changes'!$A$2:$C$100, 3, TRUE) -> 0
A33: 20 | B33: =DATE($B$3 + INT((20-1)/12), MOD(20-1, 12) + 1, 15) -> 0 | C33: =EDATE(B33, -(INT($B$4/2))) -> 0 | D33: =VLOOKUP(C33, '1_Rate_Changes'!$A$2:$C$100, 3, TRUE) -> 0 | E33: =IF(20<=$B$4, 20, (2*$B$4)-20+1) -> 0 | G33: 0 | H33: 30 | I33: =INT(DATE($B$3,1,1) + (0+0.5)*365/50) -> 0 | J33: =I33 - INT(ROUND($B$4 * 30.4375, 0) * (30+0.5)/50) -> 0 | K33: =VLOOKUP(J33, '1_Rate_Changes'!$A$2:$C$100, 3, TRUE) -> 0
A34: 21 | B34: =DATE($B$3 + INT((21-1)/12), MOD(21-1, 12) + 1, 15) -> 0 | C34: =EDATE(B34, -(INT($B$4/2))) -> 0 | D34: =VLOOKUP(C34, '1_Rate_Changes'!$A$2:$C$100, 3, TRUE) -> 0 | E34: =IF(21<=$B$4, 21, (2*$B$4)-21+1) -> 0 | G34: 0 | H34: 31 | I34: =INT(DATE($B$3,1,1) + (0+0.5)*365/50) -> 0 | J34: =I34 - INT(ROUND($B$4 * 30.4375, 0) * (31+0.5)/50) -> 0 | K34: =VLOOKUP(J34, '1_Rate_Changes'!$A$2:$C$100, 3, TRUE) -> 0
A35: 22 | B35: =DATE($B$3 + INT((22-1)/12), MOD(22-1, 12) + 1, 15) -> 0 | C35: =EDATE(B35, -(INT($B$4/2))) -> 0 | D35: =VLOOKUP(C35, '1_Rate_Changes'!$A$2:$C$100, 3, TRUE) -> 0 | E35: =IF(22<=$B$4, 22, (2*$B$4)-22+1) -> 0 | G35: 0 | H35: 32 | I35: =INT(DATE($B$3,1,1) + (0+0.5)*365/50) -> 0 | J35: =I35 - INT(ROUND($B$4 * 30.4375, 0) * (32+0.5)/50) -> 0 | K35: =VLOOKUP(J35, '1_Rate_Changes'!$A$2:$C$100, 3, TRUE) -> 0
A36: 23 | B36: =DATE($B$3 + INT((23-1)/12), MOD(23-1, 12) + 1, 15) -> 0 | C36: =EDATE(B36, -(INT($B$4/2))) -> 0 | D36: =VLOOKUP(C36, '1_Rate_Changes'!$A$2:$C$100, 3, TRUE) -> 0 | E36: =IF(23<=$B$4, 23, (2*$B$4)-23+1) -> 0 | G36: 0 | H36: 33 | I36: =INT(DATE($B$3,1,1) + (0+0.5)*365/50) -> 0 | J36: =I36 - INT(ROUND($B$4 * 30.4375, 0) * (33+0.5)/50) -> 0 | K36: =VLOOKUP(J36, '1_Rate_Changes'!$A$2:$C$100, 3, TRUE) -> 0
A37: 24 | B37: =DATE($B$3 + INT((24-1)/12), MOD(24-1, 12) + 1, 15) -> 0 | C37: =EDATE(B37, -(INT($B$4/2))) -> 0 | D37: =VLOOKUP(C37, '1_Rate_Changes'!$A$2:$C$100, 3, TRUE) -> 0 | E37: =IF(24<=$B$4, 24, (2*$B$4)-24+1) -> 0 | G37: 0 | H37: 34 | I37: =INT(DATE($B$3,1,1) + (0+0.5)*365/50) -> 0 | J37: =I37 - INT(ROUND($B$4 * 30.4375, 0) * (34+0.5)/50) -> 0 | K37: =VLOOKUP(J37, '1_Rate_Changes'!$A$2:$C$100, 3, TRUE) -> 0
C38: Totals: | D38: =SUMPRODUCT(D14:D37, E14:E37) -> 0 | E38: =SUM(E14:E37) -> 0 | G38: 0 | H38: 35 | I38: =INT(DATE($B$3,1,1) + (0+0.5)*365/50) -> 0 | J38: =I38 - INT(ROUND($B$4 * 30.4375, 0) * (35+0.5)/50) -> 0 | K38: =VLOOKUP(J38, '1_Rate_Changes'!$A$2:$C$100, 3, TRUE) -> 0
C39: Avg Level: | D39: =D38/E38 -> 0 | G39: 0 | H39: 36 | I39: =INT(DATE($B$3,1,1) + (0+0.5)*365/50) -> 0 | J39: =I39 - INT(ROUND($B$4 * 30.4375, 0) * (36+0.5)/50) -> 0 | K39: =VLOOKUP(J39, '1_Rate_Changes'!$A$2:$C$100, 3, TRUE) -> 0
C40: PY Factor: | D40: =$B$5/D39 -> 0 | G40: 0 | H40: 37 | I40: =INT(DATE($B$3,1,1) + (0+0.5)*365/50) -> 0 | J40: =I40 - INT(ROUND($B$4 * 30.4375, 0) * (37+0.5)/50) -> 0 | K40: =VLOOKUP(J40, '1_Rate_Changes'!$A$2:$C$100, 3, TRUE) -> 0
...
